Workbook
Name Datenschnitt_Anzahl_Einsatzpläne: #N/A
Name dropdown_abrechnung: AA!$A$287:$A$299
Name RHHLogo: INDIRECT(Dispoauftrag!$A$26)
Name SenderkombiEvents: AA!$A$21:$A$24
Name Senderkombis: AA!$A$11:$A$12
Name SenderKombisOA: AA!$A$17
Name SenderKombisUKW: AA!$A$13:$A$20
Name targeting: AA!$A$152:$A$154
Name targeting_spec: AA!$E$159:$E$284
Name undoder: AA!$A$148:$A$149
Name WerbemittelEvents: AA!$A$68
Name WerbemittelKombi: AA!$A$33:$A$41
Name WerbemittelOA: AA!$A$69:$A$75
Name WerbemittelPodcast: AA!$A$76:$A$78
Name WerbemittelUKW: AA!$A$33:$A$67

Sheet Dispoauftrag
B1: Dispoauftrag
B2: Rote Felder sind Pflichtfelder! | E2: (Bitte beachten, dass dieser in SalesForce hinterlegt sein muss!)
B3: Grüne Felder sind optional!
B4: Blaue Felder werden automatisch ausgefüllt | E4: Bitte X bei Rechnungsempfänger! | F4: Meridian-Nr.
B5: Kunde:
B6: Agentur:
B7: Ansprechpartner:
B8: E-Mail Ansprechpartner:
B9: AE-fähig:
B10: Produkt / Titel der Kampagne:
B11: Erstellt am:
B12: Mediaberater:
B13: Kalkulation geprüft:
B14: Höhe Payfaktor ohne OA
B15: Höhe Payfaktor OA
B16: Freigabe PF durch:
... B24: Welche Auftragsbestätigung ist gewünscht?
B27: Wie soll die Auftragsbestätigung versandt werden? | F27: Dieser Dispositionsauftrag beinhaltet folgende Sender
D28: über Dispo | F28: Bitte beachte, bei Verwendung mehrerer Kombis gibt es auch entsprechend mehrere AB's und Rechnungen!
F30: =IF(OR($D$44=AA!A11,$D$74=AA!A11,$D$104=AA!A11,$D$134=AA!A11,$D$164=AA!A11,$D$194=AA!A11,$D$224=AA!A11,$D$254=AA!A11,$D$284=AA!A11,$D$314=AA!A11,$D$344=AA!A11,$D$374=AA!A11,$D$404=AA!A11,$D$434=AA!A11,$D$464=AA!A11,$D$494=AA!A11,$D$524=AA!A11,$D$554=AA!A11,$D$584=AA!A11,$D$614=AA!A11),AA!A11,"")
F31: =IF(OR($D$44=AA!A12,$D$74=AA!A12,$D$104=AA!A12,$D$134=AA!A12,$D$164=AA!A12,$D$194=AA!A12,$D$224=AA!A12,$D$254=AA!A12,$D$284=AA!A12,$D$314=AA!A12,$D$344=AA!A12,$D$374=AA!A12,$D$404=AA!A12,$D$434=AA!A12,$D$464=AA!A12,$D$494=AA!A12,$D$524=AA!A12,$D$554=AA!A12,$D$584=AA!A12,$D$614=AA!A12),AA!A12,"")
B32: Mediabrutto | D32: =SUM(D68:D70)+SUM(D98:D100)+SUM(D128:D130)+SUM(D158:D160)+SUM(D188:D190)+SUM(D218:D220)+SUM(D248:D250)+SUM(D278:D280)+SUM(D308:D310)+SUM(D338:D340)+SUM(D368:D370)+SUM(D398:D400)+SUM(D428:D430)+SUM(D458:D460)+SUM(D488:D490)+SUM(D518:D520)+SUM(D548:D550)+SUM(D578:D580)+SUM(D608:D610)+SUM(D638:D640) -> 0 | F32: =IF(OR($D$44=AA!A13,$D$74=AA!A13,$D$104=AA!A13,$D$134=AA!A13,$D$164=AA!A13,$D$194=AA!A13,$D$224=AA!A13,$D$254=AA!A13,$D$284=AA!A13,$D$314=AA!A13,$D$344=AA!A13,$D$374=AA!A13,$D$404=AA!A13,$D$434=AA!A13,$D$464=AA!A13,$D$494=AA!A13,$D$524=AA!A13,$D$554=AA!A13,$D$584=AA!A13,$D$614=AA!A13),AA!A13,"")
B33: Mediabrutto I (nach Cash-Rabatt) | D33: =(D68-(D68*E68))+(D69-(D69*E69))+(D70-(D70*E70)) +(D98-(D98*E98))+(D99-(D99*E99))+(D100-(D100*E100)) +(D128-(D128*E128))+(D129-(D129*E129))+(D130-(D130*E130)) +(D158-(D158*E158))+(D159-(D159*E159))+(D160-(D160*E160)) +(D188-(D188*E188))+(D189-(D189*E189))+(D190-(D190*E190)) +(D218-(D218*E218))+(D219-(D219*E219))+(D220-(D220*E220)) +(D248-(D248*E248))+(D249-(D249*E249))+(D250-(D250*E250)) +(D278-(D278*E278))+(D279-(D279*E279))+(D280-(D280*E280)) +(D308-(D308*E308))+(D309-(D309*E309))+(D310-(D310*E310)) +(D338-(D338*E338))+(D339-(D339*E339))+(D340-(D340*E340)) +(D368-(D368*E368))+(D369-(D369*E369))+(D370-(D370*E370)) +(D398-(D398*E398))+(D399-(D399*E399))+(D400-(D400*E400)) +(D428-(D428*E428))+(D429-(D429*E429))+(D430-(D430*E430)) +(D458-(D458*E458))+(D459-(D459*E459))+(D460-(D460*E460)) +(D488-(D488*E488))+(D489-(D489*E489))+(D490-(D490*E490)) +(D518-(D518*E518))+(D519-(D519*E519))+(D520-(D520*E520)) +(D548-(D548*E548))+(D549-(D549*E549))+(D550-(D550*E550)) +(D578-(D578*E578))+(D579-(D579*E579))+(D580-(D580*E580)) +(D608-(D608*E608))+(D609-(D609*E609))+(D610-(D610*E610)) +(D638-(D638*E638))+(D639-(D639*E639))+(D640-(D640*E640)) -> 0 | F33: =IF(OR($D$44=AA!A14,$D$74=AA!A14,$D$104=AA!A14,$D$134=AA!A14,$D$164=AA!A14,$D$194=AA!A14,$D$224=AA!A14,$D$254=AA!A14,$D$284=AA!A14,$D$314=AA!A14,$D$344=AA!A14,$D$374=AA!A14,$D$404=AA!A14,$D$434=AA!A14,$D$464=AA!A14,$D$494=AA!A14,$D$524=AA!A14,$D$554=AA!A14,$D$584=AA!A14,$D$614=AA!A14),AA!A14,"")
B34: AE | D34: =IF(F68="ja", (D68-(D68*E68)) * 0.15, 0) +IF(F69="ja", (D69-(D69*E69)) * 0.15, 0) +IF(F70="ja", (D70-(D70*E70)) * 0.15, 0) +IF(F98="ja", (D98-(D98*E98)) * 0.15, 0) +IF(F99="ja", (D99-(D99*E99)) * 0.15, 0) +IF(F100="ja", (D100-(D100*E100)) * 0.15, 0) +IF(F128="ja", (D128-(D128*E128)) * 0.15, 0) +IF(F129="ja", (D129-(D129*E129)) * 0.15, 0) +IF(F130="ja", (D130-(D130*E130)) * 0.15, 0) +IF(F158="ja", (D158-(D158*E158)) * 0.15, 0) +IF(F159="ja", (D159-(D159*E159)) * 0.15, 0) +IF(F160="ja", (D160-(D160*E160)) * 0.15, 0) +IF(F188="ja", (D188-(D188*E188)) * 0.15, 0) +IF(F189="ja", (D189-(D189*E189)) * 0.15, 0) +IF(F190="ja", (D190-(D190*E190)) * 0.15, 0) +IF(F218="ja", (D218-(D218*E218)) * 0.15, 0) +IF(F219="ja", (D219-(D219*E219)) * 0.15, 0) +IF(F220="ja", (D220-(D220*E220)) * 0.15, 0) +IF(F248="ja", (D248-(D248*E248)) * 0.15, 0) +IF(F249="ja", (D249-(D249*E249)) * 0.15, 0) +IF(F250="ja", (D250-(D250*E250)) * 0.15, 0) +IF(F278="ja", (D278-(D278*E278)) * 0.15, 0) +IF(F279="ja", (D279-(D279*E279)) * 0.15, 0) +IF(F280="ja", (D280-(D280*E280)) * 0.15, 0) +IF(F308="ja", (D308-(D308*E308)) * 0.15, 0) +IF(F309="ja", (D309-(D309*E309)) * 0.15, 0) +IF(F310="ja", (D310-(D310*E310)) * 0.15, 0) +IF(F338="ja", (D338-(D338*E338)) * 0.15, 0) +IF(F339="ja", (D339-(D339*E339)) * 0.15, 0) +IF(F340="ja", (D340-(D340*E340)) * 0.15, 0) +IF(F368="ja", (D368-(D368*E368)) * 0.15, 0) +IF(F369="ja", (D369-(D369*E369)) * 0.15, 0) +IF(F370="ja", (D370-(D370*E370)) * 0.15, 0) +IF(F398="ja", (D398-(D398*E398)) * 0.15, 0) +IF(F399="ja", (D399-(D399*E399)) * 0.15, 0) +IF(F400="ja", (D400-(D400*E400)) * 0.15, 0) +IF(F428="ja", (D428-(D428*E428)) * 0.15, 0) +IF(F429="ja", (D429-(D429*E429)) * 0.15, 0) +IF(F430="ja", (D430-(D430*E430)) * 0.15, 0) +IF(F458="ja", (D458-(D458*E458)) * 0.15, 0) +IF(F459="ja", (D459-(D459*E459)) * 0.15, 0) +IF(F460="ja", (D460-(D460*E460)) * 0.15, 0) +IF(F488="ja", (D488-(D488*E488)) * 0.15, 0) +IF(F489="ja", (D489-(D489*E489)) * 0.15, 0) +IF(F490="ja", (D490-(D490*E490)) * 0.15, 0) +IF(F518="ja", (D518-(D518*E518)) * 0.15, 0) +IF(F519="ja", (D519-(D519*E519)) * 0.15, 0) +IF(F520="ja", (D520-(D520*E520)) * 0.15, 0) +IF(F548="ja", (D548-(D548*E548)) * 0.15, 0) +IF(F549="ja", (D549-(D549*E549)) * 0.15, 0) +IF(F550="ja", (D550-(D550*E550)) * 0.15, 0) +IF(F578="ja", (D578-(D578*E578)) * 0.15, 0) +IF(F579="ja", (D579-(D579*E579)) * 0.15, 0) +IF(F580="ja", (D580-(D580*E580)) * 0.15, 0) +IF(F608="ja", (D608-(D608*E608)) * 0.15, 0) +IF(F609="ja", (D609-(D609*E609)) * 0.15, 0) +IF(F610="ja", (D610-(D610*E610)) * 0.15, 0) +IF(F638="ja", (D638-(D638*E638)) * 0.15, 0) +IF(F639="ja", (D639-(D639*E639)) * 0.15, 0) +IF(F640="ja", (D640-(D640*E640)) * 0.15, 0) -> 0 | F34: =IF(OR($D$44=AA!A15,$D$74=AA!A15,$D$104=AA!A15,$D$134=AA!A15,$D$164=AA!A15,$D$194=AA!A15,$D$224=AA!A15,$D$254=AA!A15,$D$284=AA!A15,$D$314=AA!A15,$D$344=AA!A15,$D$374=AA!A15,$D$404=AA!A15,$D$434=AA!A15,$D$464=AA!A15,$D$494=AA!A15,$D$524=AA!A15,$D$554=AA!A15,$D$584=AA!A15,$D$614=AA!A15),AA!A15,"")
B35: N/N Gesamt Invest | D35: =G71+G101+G131+G161+G191+G221+G251+G281+G311+G341+G371+G401+G431+G461+G491+G521+G551+G581+G611+G641 -> 0 | F35: =IF(OR($D$44=AA!A16,$D$74=AA!A16,$D$104=AA!A16,$D$134=AA!A16,$D$164=AA!A16,$D$194=AA!A16,$D$224=AA!A16,$D$254=AA!A16,$D$284=AA!A16,$D$314=AA!A16,$D$344=AA!A16,$D$374=AA!A16,$D$404=AA!A16,$D$434=AA!A16,$D$464=AA!A16,$D$494=AA!A16,$D$524=AA!A16,$D$554=AA!A16,$D$584=AA!A16,$D$614=AA!A16),AA!A16,"")
F36: =IF(OR($D$44=AA!A17,$D$74=AA!A17,$D$104=AA!A17,$D$134=AA!A17,$D$164=AA!A17,$D$194=AA!A17,$D$224=AA!A17,$D$254=AA!A17,$D$284=AA!A17,$D$314=AA!A17,$D$344=AA!A17,$D$374=AA!A17,$D$404=AA!A17,$D$434=AA!A17,$D$464=AA!A17,$D$494=AA!A17,$D$524=AA!A17,$D$554=AA!A17,$D$584=AA!A17,$D$614=AA!A17),AA!A17,"")
F37: =IF(OR($D$44=AA!A18,$D$74=AA!A18,$D$104=AA!A18,$D$134=AA!A18,$D$164=AA!A18,$D$194=AA!A18,$D$224=AA!A18,$D$254=AA!A18,$D$284=AA!A18,$D$314=AA!A18,$D$344=AA!A18,$D$374=AA!A18,$D$404=AA!A18,$D$434=AA!A18,$D$464=AA!A18,$D$494=AA!A18,$D$524=AA!A18,$D$554=AA!A18,$D$584=AA!A18,$D$614=AA!A18),AA!A18,"")
F38: =IF(OR($D$44=AA!A19,$D$74=AA!A19,$D$104=AA!A19,$D$134=AA!A19,$D$164=AA!A19,$D$194=AA!A19,$D$224=AA!A19,$D$254=AA!A19,$D$284=AA!A19,$D$314=AA!A19,$D$344=AA!A19,$D$374=AA!A19,$D$404=AA!A19,$D$434=AA!A19,$D$464=AA!A19,$D$494=AA!A19,$D$524=AA!A19,$D$554=AA!A19,$D$584=AA!A19,$D$614=AA!A19),AA!A19,"")
B39: ="Dieser Auftrag enthält " & SUM(IF(LEN(D44)>2,1,0), IF(LEN(D74)>2,1,0), IF(LEN(D104)>2,1,0), IF(LEN(D134)>2,1,0), IF(LEN(D164)>2,1,0), IF(LEN(D194)>2,1,0), IF(LEN(D224)>2,1,0), IF(LEN(D254)>2,1,0), IF(LEN(D284)>2,1,0), IF(LEN(D314)>2,1,0), IF(LEN(D344)>2,1,0), IF(LEN(D374)>2,1,0), IF(LEN(D404)>2,1,0), IF(LEN(D434)>2,1,0), IF(LEN(D464)>2,1,0), IF(LEN(D494)>2,1,0), IF(LEN(D524)>2,1,0), IF(LEN(D554)>2,1,0), IF(LEN(D584)>2,1,0), IF(LEN(D614)>2,1,0)) & " Einsatzpläne!" -> Dieser Auftrag enthält 0 Einsatzpläne! | F39: =IF(OR($D$44=AA!A20,$D$74=AA!A20,$D$104=AA!A20,$D$134=AA!A20,$D$164=AA!A20,$D$194=AA!A20,$D$224=AA!A20,$D$254=AA!A20,$D$284=AA!A20,$D$314=AA!A20,$D$344=AA!A20,$D$374=AA!A20,$D$404=AA!A20,$D$434=AA!A20,$D$464=AA!A20,$D$494=AA!A20,$D$524=AA!A20,$D$554=AA!A20,$D$584=AA!A20,$D$614=AA!A20),AA!A20,"")
B40: Hier können weitere Einsatzpläne hinzugefügt werden (Klick auf die Filtertüte)
A41: Anzahl Einsatzpläne
A42: Plan 01 | B42: Einsatzpläne Spots/SWF/Online Audio:
A43: Plan 01 | E43: NF Hinweis
A44: Plan 01 | B44: Sender/Inventar: | E44: =IF(D44=AA!$A$18,"WerbemittelPodcast", IF(COUNTIF(AA!$A$21:$A$24,D44)>0,"WerbemittelEvents", IF(OR(D44=AA!$A$17,D44=AA!$A$11,D44=AA!$A$12), IF(D44=AA!$A$17,"WerbemittelOA","WerbemittelKombi"), "WerbemittelUKW"))) -> WerbemittelUKW | F44: =IF(OR(AA!$A$21=D44, AA!$A$22=D44, AA!$A$23=D44, AA!$A$24=D44), "Bitte gib die Event- Kostenstelle ein", "")
A45: Plan 01 | B45: Werbemittel: | E45: =IF(OR(ISNUMBER(MATCH(D45,AA!$A$33:$A$41,0)),ISNUMBER(MATCH(D45,AA!$A$48,0)),ISNUMBER(MATCH(D45,AA!$A$55:$A$59,0)),ISNUMBER(MATCH(D45,AA!$A$69:$A$78,0))),"Liegen die Nutzungsrechte vor? (nur bei über Krane&Raabe produzierte Spots)","")
A46: Plan 01 | B46: HR-Kampagne? | E46: =IF(D46="ja","Soll eine Verpackung eingeplant werden?","") | F46: nein
A47: Plan 01 | B47: Länge in Sek: | E47: =IF(OR(ISNUMBER(MATCH(D45,AA!$A$64:$A$65,0)),),"Gib hier ggf. den Boosterbetrag ein.","")
A48: Plan 01 | B48: Kampagnenzeitraum:
A49: Plan 01 | B49: Tage
A50: Plan 01 | B50: Uhrzeiten | E50: =IF(OR(D45=AA!$A$42,D45=AA!$A$44,D45=AA!$A$46,D45=AA!$A$47,D45=AA!$A$48,D45=AA!$A$49,D45=AA!$A$50,D45=AA!$A$51,D45=AA!$A$52,D45=AA!$A$53,D45=AA!$A$54,D45=AA!$A$55,D45=AA!$A$56,D45=AA!$A$57,D45=AA!$A$58,D45=AA!$A$59), "Überprüfe die Einsatzpläne und Uhrzeiten im Hinblick auf Sinnhaftigkeit. (Bspw. keine Promo nach PayOff)", "")
...

Sheet Einplanung durch Kombitabelle
A1: Audio-Angebot | B1: Werbeformat | C1: Einplanung durch?
A2: CARAVAN.fm | B2: Abbinder | C2: Disposition
A3: CARAVAN.fm | B3: Allonge | C3: Disposition
A4: CARAVAN.fm | B4: Bumper | C4: OAP
A5: CARAVAN.fm | B5: Closer | C5: darf nicht geplant werden
A6: CARAVAN.fm | B6: Gegengeschäft | C6: Disposition
A7: CARAVAN.fm | B7: Gewinnspiel/Pay-Off | C7: OAP
A8: CARAVAN.fm | B8: Influencer-Spot | C8: Disposition
A9: CARAVAN.fm | B9: Influencer-Spot als Single-Spot | C9: Disposition
A10: CARAVAN.fm | B10: Infomercial / Profi-Tipp | C10: Disposition
A11: CARAVAN.fm | B11: In-Stream | C11: PDM-Digital / Niklas Farin
A12: CARAVAN.fm | B12: In-Stream Influencer | C12: PDM-Digital / Niklas Farin
... A238: MORE-Kombi Online Audio | B238: Visual-Spot als Single-Spot | C238: Disposition
A239: MORE-Kombi Online Audio | B239: Visual-Spot mit .de-Nennung | C239: Disposition | D239: Disposition
A240: MORE-Kombi Online Audio | B240: Werbespot | C240: Disposition | D240: PDM-Digital / Niklas Farin
A241: MORE-Kombi Online Audio | B241: Werbespot erstplatziert | C241: Disposition | D241: OAP
A242: MORE-Kombi Online Audio | B242: Werbespot letztplatziert | C242: Disposition | D242: Redaktion
A243: MORE-Kombi Online Audio | B243: Mid-Roll Spotify / Deezer / Youtube Musikumfeld | C243: PDM-Digital / Niklas Farin | D243: Events
A244: MORE-Kombi Events CARAVAN.fm | B244: Off-Air | C244: Events | D244: Influencer
A245: MORE-Kombi Events 80er 90er OLDIE ANTENNE Hamburg | B245: Off-Air | C245: Events | D245: darf nicht geplant werden
A246: MORE-Kombi Events Radio Hamburg | B246: Off-Air | C246: Events
A247: MORE-Kombi Events ROCK ANTENNE Hamburg | B247: Off-Air | C247: Events
A248: MORE-Kombi Podcast | B248: Abbinder | C248: darf nicht geplant werden
A249: MORE-Kombi Podcast | B249: Allonge | C249: darf nicht geplant werden
A250: MORE-Kombi Podcast | B250: Bumper | C250: PDM-Digital / Niklas Farin
A251: MORE-Kombi Podcast | B251: Closer | C251: darf nicht geplant werden
A252: MORE-Kombi Podcast | B252: Gegengeschäft | C252: PDM-Digital / Niklas Farin
A253: MORE-Kombi Podcast | B253: Gewinnspiel/Pay-Off | C253: darf nicht geplant werden
A254: MORE-Kombi Podcast | B254: Influencer-Spot | C254: PDM-Digital / Niklas Farin
A255: MORE-Kombi Podcast | B255: Influencer-Spot als Single-Spot | C255: darf nicht geplant werden
A256: MORE-Kombi Podcast | B256: Infomercial / Profi-Tipp | C256: darf nicht geplant werden
A257: MORE-Kombi Podcast | B257: In-Stream | C257: PDM-Digital / Niklas Farin
... A411: 80er 90er OLDIE ANTENNE Hamburg | B411: Event-Tipp | C411: Disposition

Sheet AA
A1: Auswahlfelder
A3: ja
A4: nein
A5: teilweise
A8: X
A11: MORE Hamburg-Kombi
A12: MORE Hamburg-Kombi+
A13: Radio Hamburg
A14: ROCK ANTENNE Hamburg
A15: 80er 90er OLDIE ANTENNE Hamburg
A16: CARAVAN.fm
A17: MORE-Kombi Online Audio
... A24: MORE-Kombi Events ROCK ANTENNE Hamburg
A33: Werbespot | D33: Dispo
A34: Werbespot erstplatziert | D34: Dispo
A35: Werbespot letztplatziert | D35: Dispo
A36: Single-Spot | D36: Dispo
A37: Showsponsoring-Single-Spot | D37: Dispo
A38: Tandem / Reminder | D38: Dispo
A39: Tridem | D39: Dispo
A40: Jobspot | D40: Dispo
A41: Gegengeschäft | B41: B
A42: Promo/Moderation | B42: K | D42: OAP
A43: Event-Tipp
A44: Veranstaltungstipp | B44: K | D44: bei RHH Redaktion, bei HH2 OAP, bei RAHH Redaktion
A45: Preseller
A46: Trailer/Vorpr. Element Station Voice | B46: K | D46: Dispo
A47: Abbinder | B47: K | D47: Bei RAHH dann Dispo | E47: bei St. Pauli Backstage OAP
A48: Allonge | B48: K | D48: Dispo
A49: Opener | B49: K | D49: OAP | E49: Wetter, Citylife bei Dispo
A50: Bumper | B50: K | D50: OAP | E50: Wetter, Citylife bei Dispo
A51: Stinger | B51: K | D51: bei RHH Dispo, bei HH2 OAP
A52: Closer | B52: K | D52: OAP, bei Chartshow Dispo | E52: Wetter, Citylife bei Dispo
A53: Gewinnspiel/Pay-Off | B53: K | D53: OAP
A54: Sondersendung (4x90Sek) | B54: K | D54: Dispo
A55: Influencer-Spot | B55: K | D55: Dispo
A56: Influencer-Spot als Single-Spot | B56: K | D56: Dispo
A57: Infomercial / Profi-Tipp | B57: K | D57: Dispo
A58: Visual-Spot als Single-Spot | B58: K | D58: Dispo
A59: Visual-Spot mit .de-Nennung | B59: K | D59: Dispo
...

Sheet Buchungskenn durch Kombitabelle
B1: MORE Hamburg-Kombi | C1: MORE Hamburg-Kombi+ | D1: Radio Hamburg | E1: ROCK ANTENNE Hamburg | F1: 80er 90er OLDIE ANTENNE Hamburg | G1: CARAVAN.fm | H1: MORE-Kombi Online Audio | I1: MORE-Kombi Podcast | J1: ffn Hamburg Plus | K1: RADIO BOLLERWAGEN DAB+ Hamburg | L1: MORE-Kombi Events Radio Hamburg | M1: MORE-Kombi Events 80er 90er OLDIE ANTENNE Hamburg | N1: MORE-Kombi Events CARAVAN.fm | O1: MORE-Kombi Events ROCK ANTENNE Hamburg
A2: Werbespot | B2: Spots (L) | C2: Spots (L) | D2: Spots (L) | E2: Spots (L) | F2: Spots (L) | G2: UC | J2: Spots (L) | K2: Spots (L)
A3: Werbespot erstplatziert | B3: Spots (L) | C3: Spots (L) | D3: Spots (L) | E3: Spots (L) | F3: Spots (L) | G3: UC | J3: Spots (L) | K3: Spots (L) | T3: Zur Verfügung
A4: Werbespot letztplatziert | B4: Spots (L) | C4: Spots (L) | D4: Spots (L) | E4: Spots (L) | F4: Spots (L) | G4: UC | J4: Spots (L) | K4: Spots (L) | T4: Online Audio (UA)
A5: Single-Spot | B5: Spots (L) | C5: Spots (L) | D5: Spots (L) | E5: Spots (L) | F5: Spots (L) | G5: UC | J5: Spots (L) | K5: Spots (L) | T5: U (Online SWF)
A6: Showsponsoring-Single-Spot | E6: Spots (L) | G6: UC | T6: US (Social Media)
A7: Tandem / Reminder | B7: Spots (L) | C7: Spots (L) | D7: Spots (L) | E7: Spots (L) | F7: Spots (L) | G7: UC | J7: Spots (L) | K7: Spots (L) | T7: UD (Display Ads)
A8: Tridem | B8: Spots (L) | C8: Spots (L) | D8: Spots (L) | E8: Spots (L) | F8: Spots (L) | G8: UC | J8: Spots (L) | K8: Spots (L) | T8: UJ (Jobbörse)
A9: Jobspot | B9: Spots (L) | C9: Spots (L) | D9: Spots (L) | E9: Spots (L) | F9: Spots (L) | G9: UC | J9: Spots (L) | K9: Spots (L) | T9: UI (Mod-Influencer)
A10: Gegengeschäft | B10: Gegengeschäft (B) | C10: Gegengeschäft (B) | D10: Gegengeschäft (B) | E10: Gegengeschäft (B) | F10: Gegengeschäft (B) | G10: Gegengeschäft (B) | J10: Gegengeschäft (B) | K10: Gegengeschäft (B) | T10: Spots (L)
A11: Promo/Moderation | D11: SWF (K) | E11: SWF (K) | F11: SWF (K) | G11: UC | T11: SWF (K)
A12: Event-Tipp | F12: SWF (K)
A13: Veranstaltungstipp | D13: SWF (K) | E13: SWF (K) | F13: SWF (K) | G13: UC | T13: Events/Promotion (P)
A14: Preseller | E14: SWF (K)
A15: Trailer/Vorpr. Element Station Voice | D15: SWF (K) | E15: SWF (K) | F15: SWF (K) | G15: UC | T15: UC
A16: Abbinder | D16: SWF (K) | E16: SWF (K) | F16: SWF (K) | G16: UC | T16: Gegengeschäft (B)
A17: Allonge | D17: SWF (K) | E17: SWF (K) | F17: SWF (K) | G17: UC
A18: Opener | D18: SWF (K) | E18: SWF (K) | F18: SWF (K) | G18: UC
A19: Bumper | D19: SWF (K) | E19: SWF (K) | F19: SWF (K) | G19: UC
A20: Stinger | D20: SWF (K) | E20: SWF (K) | F20: SWF (K) | G20: UC
A21: Closer | D21: SWF (K) | E21: SWF (K) | F21: SWF (K) | G21: UC
A22: Gewinnspiel/Pay-Off | D22: SWF (K) | E22: SWF (K) | F22: SWF (K) | G22: UC
A23: Sondersendung (4x90Sek) | D23: SWF (K) | E23: SWF (K) | F23: SWF (K) | G23: UC
A24: Influencer-Spot | D24: SWF (K) | E24: SWF (K) | F24: SWF (K) | G24: UC
A25: Influencer-Spot als Single-Spot | D25: SWF (K) | E25: SWF (K) | F25: SWF (K) | G25: UC
A26: Infomercial / Profi-Tipp | D26: SWF (K) | E26: SWF (K) | F26: SWF (K) | G26: UC
A27: Visual-Spot als Single-Spot | D27: SWF (K) | E27: SWF (K) | F27: SWF (K) | G27: UC
A28: Visual-Spot mit .de-Nennung | D28: SWF (K) | E28: SWF (K) | F28: SWF (K) | G28: UC
A29: Presenting-Spot | D29: SWF (K) | F29: SWF (K)
A30: Online Anzeigencontainer | D30: U (Online SWF) | E30: U (Online SWF) | F30: U (Online SWF) | G30: UC
A31: Online Facebook | D31: US (Social Media) | E31: US (Social Media) | F31: US (Social Media) | G31: UC
A32: Online GWS | D32: U (Online SWF) | E32: U (Online SWF) | F32: U (Online SWF) | G32: UC
A33: Online Instagram | D33: US (Social Media) | E33: US (Social Media) | F33: US (Social Media) | G33: UC
A34: Online Instagram (Influencer) | D34: UI (Mod-Influencer) | E34: UI (Mod-Influencer) | F34: UI (Mod-Influencer) | G34: UC
A35: Online Sondersendung | D35: U (Online SWF) | E35: U (Online SWF) | F35: U (Online SWF) | G35: UC
A36: Online TikTok | D36: US (Social Media) | E36: US (Social Media) | F36: US (Social Media) | G36: UC
A37: Off-Air | L37: Events/Promotion (P) | M37: Events/Promotion (P) | N37: Events/Promotion (P) | O37: Events/Promotion (P)
A38: Pre-Stream | B38: Online Audio (UA) | C38: Online Audio (UA) | D38: Online Audio (UA) | E38: Online Audio (UA) | F38: Online Audio (UA) | G38: Online Audio (UA) | H38: Online Audio (UA) | I38: Online Audio (UA) | J38: Online Audio (UA) | K38: Online Audio (UA)
A39: In-Stream | B39: Online Audio (UA) | C39: Online Audio (UA) | D39: Online Audio (UA) | E39: Online Audio (UA) | F39: Online Audio (UA) | G39: Online Audio (UA) | H39: Online Audio (UA) | I39: Online Audio (UA) | J39: Online Audio (UA) | K39: Online Audio (UA)
A40: Pre-/In-Stream | B40: Online Audio (UA) | C40: Online Audio (UA) | D40: Online Audio (UA) | E40: Online Audio (UA) | F40: Online Audio (UA) | G40: Online Audio (UA) | H40: Online Audio (UA) | I40: Online Audio (UA) | J40: Online Audio (UA) | K40: Online Audio (UA)
...

Sheet Versionshinweise
A1: Release | B1: Datum | C1: Neuerungen
A2: 1.0
A3: 1.1
A4: 1.2 | C4: Ergänzung Verpackung JobSpots & HR-Kampagne
A5: 1.3 | C5: Ergänzung Nutzungsrechte Spot
A6: 1.4 | B6: 45660 | C6: Ergänzung DA Reporting, Ergänzung "nach Tarif" bei Freigabe Payfaktor
A7: 1.5 | B7: 45681 | C7: Einplanung durch für Podcast ergänzt
A8: 1.6. | B8: 45687 | C8: Einplanung durch Dispo/OAP für Bumper, Stinger, Closer, Opener, und Frage nach Wettersponsoring
A9: 1.7. | B9: 45688 | C9: Mediaberater, Ricarda Bichels
A10: 1.8. | B10: 45708 | C10: Ergänzung Einplanung Durch bei Tiktok, Visual-Spot
A11: 1.9. | B11: 45714 | C11: AE-Ausweisung auf dem Deckblatt
A12: 1.10 | B12: 45728 | C12: AE-Ausweisung auf dem Deckblatt und Pläne, Zellen formatierung freigegeben, Zeilengröße freigegeben, Felder auf Deckblatt vergrößert
A13: 1.11 | B13: 45735 | C13: Ausweisung Anzahl pläne
A14: 1.12 | B14: 45791 | C14: Kombinationsmatrix Buchungskennzeichen | J14: --> alte formel | K14: =IF(D615=AA!$A$41,AA!A655, IF(AND(OR(D614=AA!$A$11,D614=AA!$A$12,D614=AA!$A$13,D614=AA!$A$14,D614=AA!$A$15,D614=AA!$A$16,D614=AA!$A$19,D614=AA!$A$20), OR(D615=AA!$A$33,D615=AA!$A$34,D615=AA!$A$35,D615=AA!$A$36,D615=AA!$A$37,D615=AA!$A$38,D615=AA!$A$39,D615=AA!$A$40,D615=AA!$A$58,D615=AA!$A$59)),AA!$A$83, IF(AND(D614=AA!$A$14,D615=AA!$A$47),AA!$A$83, IF(AND(OR(D614=AA!$A$11,D614=AA!$A$12,D614=AA!$A$13,D614=AA!$A$14,D614=AA!$A$15,D614=AA!$A$16,D614=AA!$A$19,D614=AA!$A$20), D615=AA!$A$48),AA!$A$83, IF(AND(OR(D614=AA!$A$11,D614=AA!$A$12,D614=AA!$A$13,D614=AA!$A$14,D614=AA!$A$15,D614=AA!$A$16,D614=AA!$A$19,D614=AA!$A$20), OR(D615=AA!$A$49,D615=AA!$A$50,D615=AA!$A$51)),AA!$A$85, IF(AND(OR(D614=AA!$A$11,D614=AA!$A$12,D614=AA!$A$13,D614=AA!$A$14,D614=AA!$A$15,D614=AA!$A$16,D614=AA!$A$19,D614=AA!$A$20), OR(D615=AA!$A$55,D615=AA!$A$56,D615=AA!$A$57)),AA!$A$83, IF(AND(OR(D614=AA!$A$11,D614=AA!$A$12,D614=AA!$A$13,D614=AA!$A$14,D614=AA!$A$15,D614=AA!$A$16,D614=AA!$A$19,D614=AA!$A$20), D615=AA!$A$68),AA!$A$87, IF(AND(OR(D614=AA!$A$11,D614=AA!$A$12,D614=AA!$A$13,D614=AA!$A$14,D614=AA!$A$15,D614=AA!$A$16,D614=AA!$A$19,D614=AA!$A$20), OR(D615=AA!$A$61,D615=AA!$A$62,D615=AA!$A$63,D615=AA!$A$64,D615=AA!$A$67)),AA!$A$86, IF(AND(OR(D614=AA!$A$17,D614=AA!$A$18), OR(D615=AA!$A$69,D615=AA!$A$70,D615=AA!$A$71,D615=AA!$A$72,D615=AA!$A$73,D615=AA!$A$74)),AA!$A$84, IF(AND(OR(D614=AA!$A$17,D614=AA!$A$18), OR(D615=AA!$A$76,D615=AA!$A$77,D615=AA!$A$78)),AA!$A$84, IF(AND(D615=AA!$A$54,D614=AA!$A$13),AA!$A$85, IF(AND(D615=AA!$A$54,D614=AA!$A$15),AA!$A$85, IF(AND(D615=AA!$A$54,D614=AA!$A$14),AA!$A$83, IF(AND(D615=AA!$A$54,D614=AA!$A$16),AA!$A$83, ""))))))))))))))
A15: 1.13 | B15: 45791 | C15: Kombinationsmatrix Einplanung Durch
A16: 1.14 | B16: 45803 | C16: Anpassung Kombinationsmatrix, Ergänzung Kombi-Events, Ergänzung Spotify/YoutubeMusic
A17: 1.15 | B17: 45807 | C17: Anpassung Kombinationsmatrix, Anpassung Kombi-Events
A18: 1.16 | B18: 45807 | C18: Spotify
A19: 1.17 | B19: 45818 | C19: Ergänzung KST bei Event-Kombis
A20: 1.18 | B20: 45819 | C20: Ergänzung Spotify, Deezer, Youtube bei Anstelle der MORE-Kombi Online Audio, soll das Motiv auschließlich eingeplant werden auf
A21: 1.19 | B21: 45890 | C21: Ergänzung Berechung TKP für Spotify, Hinweis zu Aufträgen von RMS hinsichtlich Provision
A22: 1.20 | B22: 45946 | C22: Ergänzung Zusatz bei Sondersendung
A23: 1.21 | B23: 45973 | C23: ergänzung Franzi, ergänzung Social Media Freigabe
A24: 1.22 | B24: 45994 | C24: Ergänzung Presenting-Spot
A25: 1.23 | B25: 46006 | C25: MORE Hamburg-Kombi und Online Audio Kombi
A26: 1.24 | B26: 46245 | C26: ergänzung namesmanager targetins und abrechnung moantlich
A27: 1.25 | B27: 46245 | C27: HH2 wird zu OAHH
