Workbook

Sheet Inhaltsverzeichnis
A1: Wo soll's hingehen?
A4: Radio Hamburg | B4: 80er 90er OAHH | C4: ROCK ANTENNE Hamburg | D4: MORE Hamburg-Kombi | E4: Hamburg-Kombi+ | F4: CARAVAN.fm | G4: RADIO BOLLERWAGEN | H4: radio ffn
A5: Preise | B5: Preise | C5: Preise | D5: Preise | E5: Preise | F5: Preise | G5: Preise | H5: Preise
A6: Planer | B6: Planer | C6: Planer | D6: Planer | E6: Planer | F6: Planer | G6: Planer | H6: Planer

Sheet Preise RHH
A1: Preise 2026 (gültig ab 1. Januar 2026) | E1: Bitte Wochentag und Zeitschine per Dropdown auswählen. Anzahl der Spots, Sekundenlänge und ggf. Rabatte eingeben
E2: Berechnung | P2: Spotlängenbonus | T2: Index
E3: Wochentag | F3: Zeitschiene | G3: Anzahl Spots | H3: Invesition pro Spot | I3: Gesamtinvestition | J3: Abzgl. Cash-Rabatt | K3: Abzgl. 15%AE | L3: N/N Invest | M3: kummulierter Rabatt | N3: Payfaktor | P3: 1 | Q3: - | R3: 15 | S3: Sekunden | T3: 110
E4: Mo-So | F4: ø 10-24 | H4: =IF($E$4=$J$11,VLOOKUP($F$4,$A$37:$K$78,11,0),IF($E$4=$H$11,VLOOKUP($F$4,$A$37:$K$78,9,0),IF($E$4=$F$11,VLOOKUP($F$4,$A$37:$K$78,7,0),IF($E$4=$D$11,VLOOKUP($F$4,$A$37:$K$78,5,0),IF($E$4=$B$11,VLOOKUP($F$4,$A$37:$K$78,3,0)))))) -> 411.42857 | I4: =H4*G4 -> 0 | L4: =(I4-(I4*J4))-(I4-(I4*J4))*K4 -> 0 | M4: =1-L4/I4 -> #DIV/0! | N4: =(1-M4)*100 -> #DIV/0! | P4: 16 | Q4: - | R4: 24 | S4: Sekunden | T4: 105
E5: Mo-Fr | F5: ø 06-18 | H5: =IF($E$5=$J$11,VLOOKUP($F$5,$A$37:$K$78,11,0),IF($E$5=$H$11,VLOOKUP($F$5,$A$37:$K$78,9,0),IF($E$5=$F$11,VLOOKUP($F$5,$A$37:$K$78,7,0),IF($E$5=$D$11,VLOOKUP($F$5,$A$37:$K$78,5,0),IF($E$5=$B$11,VLOOKUP($F$5,$A$37:$K$78,3,0)))))) -> 798 | I5: =H5*G5 -> 0 | L5: =(I5-(I5*J5))-(I5-(I5*J5))*K5 -> 0 | M5: =1-L5/I5 -> #DIV/0! | N5: =(1-M5)*100 -> #DIV/0! | P5: 25 | Q5: - | R5: 34 | S5: Sekunden | T5: 100
E6: Mo-Fr | F6: ø 06-18 | H6: =IF($E$6=$J$11,VLOOKUP($F$6,$A$37:$K$78,11,0),IF($E$6=$H$11,VLOOKUP($F$6,$A$37:$K$78,9,0),IF($E$6=$F$11,VLOOKUP($F$6,$A$37:$K$78,7,0),IF($E$6=$D$11,VLOOKUP($F$6,$A$37:$K$78,5,0),IF($E$6=$B$11,VLOOKUP($F$6,$A$37:$K$78,3,0)))))) -> 798 | I6: =H6*G6 -> 0 | L6: =(I6-(I6*J6))-(I6-(I6*J6))*K6 -> 0 | M6: =1-L6/I6 -> #DIV/0! | N6: =(1-M6)*100 -> #DIV/0! | P6: 35 | Q6: - | R6: 99 | S6: Sekunden | T6: 95
A7: Sekundenlänge: | C7: 20 | E7: Mo-Fr | F7: ø 06-18 | H7: =IF($E$7=$J$11,VLOOKUP($F$7,$A$37:$K$78,11,0),IF($E$7=$H$11,VLOOKUP($F$7,$A$37:$K$78,9,0),IF($E$7=$F$11,VLOOKUP($F$7,$A$37:$K$78,7,0),IF($E$7=$D$11,VLOOKUP($F$7,$A$37:$K$78,5,0),IF($E$7=$B$11,VLOOKUP($F$7,$A$37:$K$78,3,0)))))) -> 798 | I7: =H7*G7 -> 0 | L7: =(I7-(I7*J7))-(I7-(I7*J7))*K7 -> 0 | M7: =1-L7/I7 -> #DIV/0! | N7: =(1-M7)*100 -> #DIV/0!
A8: Single-Spot max 45 Sek. Berechnung: Länge + 50% | L8: =SUM(L4:L7) -> 0
A9: Erst-Letzt-Platzierung Berechnung: Länge + 30%
A10: SPOTPREIS
B11: Mo-Fr | D11: Sa | F11: So | H11: MO-SA | J11: MO-SO
A12: ZEITSCHIENE | B12: €/SEK. (Index 100) | C12: €/SPOT | D12: €/SEK. (Index 100) | E12: €/SPOT | F12: €/SEK. (Index 100) | G12: €/SPOT | H12: €/SEK. (Index 100) | I12: €/SPOT | J12: €/SEK. (Index 100) | K12: €/SPOT
A13: 0-1 | B13: 1 | C13: =IF(AND($C$7>=$P$5,$C$7<=$R$5),B13*$C$7*$T$5/100,IF(AND($C$7>=$P$4,$C$7<=$R$4),B13*$C$7*$T$4/100,IF(AND($C$7>=$P$3,$C$7<=$R$3),B13*$C$7*$T$3/100,IF($C$7>=$P$6,B13*$C$7*$T$6/100)))) -> 21 | D13: 1 | E13: =IF(AND($C$7>=$P$5,$C$7<=$R$5),D13*$C$7*$T$5/100,IF(AND($C$7>=$P$4,$C$7<=$R$4),D13*$C$7*$T$4/100,IF(AND($C$7>=$P$3,$C$7<=$R$3),D13*$C$7*$T$3/100,IF($C$7>=$P$6,D13*$C$7*$T$6/100)))) -> 21 | F13: 1 | G13: =IF(AND($C$7>=$P$5,$C$7<=$R$5),F13*$C$7*$T$5/100,IF(AND($C$7>=$P$4,$C$7<=$R$4),F13*$C$7*$T$4/100,IF(AND($C$7>=$P$3,$C$7<=$R$3),F13*$C$7*$T$3/100,IF($C$7>=$P$6,F13*$C$7*$T$6/100)))) -> 21 | H13: =((B13*5)+D13)/6 -> 1 | I13: =IF(AND($C$7>=$P$5,$C$7<=$R$5),H13*$C$7*$T$5/100,IF(AND($C$7>=$P$4,$C$7<=$R$4),H13*$C$7*$T$4/100,IF(AND($C$7>=$P$3,$C$7<=$R$3),H13*$C$7*$T$3/100,IF($C$7>=$P$6,H13*$C$7*$T$6/100)))) -> 21 | J13: =((B13*5)+D13+F13)/7 -> 1 | K13: =IF(AND($C$7>=$P$5,$C$7<=$R$5),J13*$C$7*$T$5/100,IF(AND($C$7>=$P$4,$C$7<=$R$4),J13*$C$7*$T$4/100,IF(AND($C$7>=$P$3,$C$7<=$R$3),J13*$C$7*$T$3/100,IF($C$7>=$P$6,J13*$C$7*$T$6/100)))) -> 21
A14: 1-2 | B14: 1 | C14: =IF(AND($C$7>=$P$5,$C$7<=$R$5),B14*$C$7*$T$5/100,IF(AND($C$7>=$P$4,$C$7<=$R$4),B14*$C$7*$T$4/100,IF(AND($C$7>=$P$3,$C$7<=$R$3),B14*$C$7*$T$3/100,IF($C$7>=$P$6,B14*$C$7*$T$6/100)))) -> 21 | D14: 1 | E14: =IF(AND($C$7>=$P$5,$C$7<=$R$5),D14*$C$7*$T$5/100,IF(AND($C$7>=$P$4,$C$7<=$R$4),D14*$C$7*$T$4/100,IF(AND($C$7>=$P$3,$C$7<=$R$3),D14*$C$7*$T$3/100,IF($C$7>=$P$6,D14*$C$7*$T$6/100)))) -> 21 | F14: 1 | G14: =IF(AND($C$7>=$P$5,$C$7<=$R$5),F14*$C$7*$T$5/100,IF(AND($C$7>=$P$4,$C$7<=$R$4),F14*$C$7*$T$4/100,IF(AND($C$7>=$P$3,$C$7<=$R$3),F14*$C$7*$T$3/100,IF($C$7>=$P$6,F14*$C$7*$T$6/100)))) -> 21 | H14: =((B14*5)+D14)/6 -> 1 | I14: =IF(AND($C$7>=$P$5,$C$7<=$R$5),H14*$C$7*$T$5/100,IF(AND($C$7>=$P$4,$C$7<=$R$4),H14*$C$7*$T$4/100,IF(AND($C$7>=$P$3,$C$7<=$R$3),H14*$C$7*$T$3/100,IF($C$7>=$P$6,H14*$C$7*$T$6/100)))) -> 21 | J14: =((B14*5)+D14+F14)/7 -> 1 | K14: =IF(AND($C$7>=$P$5,$C$7<=$R$5),J14*$C$7*$T$5/100,IF(AND($C$7>=$P$4,$C$7<=$R$4),J14*$C$7*$T$4/100,IF(AND($C$7>=$P$3,$C$7<=$R$3),J14*$C$7*$T$3/100,IF($C$7>=$P$6,J14*$C$7*$T$6/100)))) -> 21
A15: 2-3 | B15: 1 | C15: =IF(AND($C$7>=$P$5,$C$7<=$R$5),B15*$C$7*$T$5/100,IF(AND($C$7>=$P$4,$C$7<=$R$4),B15*$C$7*$T$4/100,IF(AND($C$7>=$P$3,$C$7<=$R$3),B15*$C$7*$T$3/100,IF($C$7>=$P$6,B15*$C$7*$T$6/100)))) -> 21 | D15: 1 | E15: =IF(AND($C$7>=$P$5,$C$7<=$R$5),D15*$C$7*$T$5/100,IF(AND($C$7>=$P$4,$C$7<=$R$4),D15*$C$7*$T$4/100,IF(AND($C$7>=$P$3,$C$7<=$R$3),D15*$C$7*$T$3/100,IF($C$7>=$P$6,D15*$C$7*$T$6/100)))) -> 21 | F15: 1 | G15: =IF(AND($C$7>=$P$5,$C$7<=$R$5),F15*$C$7*$T$5/100,IF(AND($C$7>=$P$4,$C$7<=$R$4),F15*$C$7*$T$4/100,IF(AND($C$7>=$P$3,$C$7<=$R$3),F15*$C$7*$T$3/100,IF($C$7>=$P$6,F15*$C$7*$T$6/100)))) -> 21 | H15: =((B15*5)+D15)/6 -> 1 | I15: =IF(AND($C$7>=$P$5,$C$7<=$R$5),H15*$C$7*$T$5/100,IF(AND($C$7>=$P$4,$C$7<=$R$4),H15*$C$7*$T$4/100,IF(AND($C$7>=$P$3,$C$7<=$R$3),H15*$C$7*$T$3/100,IF($C$7>=$P$6,H15*$C$7*$T$6/100)))) -> 21 | J15: =((B15*5)+D15+F15)/7 -> 1 | K15: =IF(AND($C$7>=$P$5,$C$7<=$R$5),J15*$C$7*$T$5/100,IF(AND($C$7>=$P$4,$C$7<=$R$4),J15*$C$7*$T$4/100,IF(AND($C$7>=$P$3,$C$7<=$R$3),J15*$C$7*$T$3/100,IF($C$7>=$P$6,J15*$C$7*$T$6/100)))) -> 21
A16: 3-4 | B16: 1 | C16: =IF(AND($C$7>=$P$5,$C$7<=$R$5),B16*$C$7*$T$5/100,IF(AND($C$7>=$P$4,$C$7<=$R$4),B16*$C$7*$T$4/100,IF(AND($C$7>=$P$3,$C$7<=$R$3),B16*$C$7*$T$3/100,IF($C$7>=$P$6,B16*$C$7*$T$6/100)))) -> 21 | D16: 1 | E16: =IF(AND($C$7>=$P$5,$C$7<=$R$5),D16*$C$7*$T$5/100,IF(AND($C$7>=$P$4,$C$7<=$R$4),D16*$C$7*$T$4/100,IF(AND($C$7>=$P$3,$C$7<=$R$3),D16*$C$7*$T$3/100,IF($C$7>=$P$6,D16*$C$7*$T$6/100)))) -> 21 | F16: 1 | G16: =IF(AND($C$7>=$P$5,$C$7<=$R$5),F16*$C$7*$T$5/100,IF(AND($C$7>=$P$4,$C$7<=$R$4),F16*$C$7*$T$4/100,IF(AND($C$7>=$P$3,$C$7<=$R$3),F16*$C$7*$T$3/100,IF($C$7>=$P$6,F16*$C$7*$T$6/100)))) -> 21 | H16: =((B16*5)+D16)/6 -> 1 | I16: =IF(AND($C$7>=$P$5,$C$7<=$R$5),H16*$C$7*$T$5/100,IF(AND($C$7>=$P$4,$C$7<=$R$4),H16*$C$7*$T$4/100,IF(AND($C$7>=$P$3,$C$7<=$R$3),H16*$C$7*$T$3/100,IF($C$7>=$P$6,H16*$C$7*$T$6/100)))) -> 21 | J16: =((B16*5)+D16+F16)/7 -> 1 | K16: =IF(AND($C$7>=$P$5,$C$7<=$R$5),J16*$C$7*$T$5/100,IF(AND($C$7>=$P$4,$C$7<=$R$4),J16*$C$7*$T$4/100,IF(AND($C$7>=$P$3,$C$7<=$R$3),J16*$C$7*$T$3/100,IF($C$7>=$P$6,J16*$C$7*$T$6/100)))) -> 21
A17: 4-5 | B17: 1 | C17: =IF(AND($C$7>=$P$5,$C$7<=$R$5),B17*$C$7*$T$5/100,IF(AND($C$7>=$P$4,$C$7<=$R$4),B17*$C$7*$T$4/100,IF(AND($C$7>=$P$3,$C$7<=$R$3),B17*$C$7*$T$3/100,IF($C$7>=$P$6,B17*$C$7*$T$6/100)))) -> 21 | D17: 1 | E17: =IF(AND($C$7>=$P$5,$C$7<=$R$5),D17*$C$7*$T$5/100,IF(AND($C$7>=$P$4,$C$7<=$R$4),D17*$C$7*$T$4/100,IF(AND($C$7>=$P$3,$C$7<=$R$3),D17*$C$7*$T$3/100,IF($C$7>=$P$6,D17*$C$7*$T$6/100)))) -> 21 | F17: 1 | G17: =IF(AND($C$7>=$P$5,$C$7<=$R$5),F17*$C$7*$T$5/100,IF(AND($C$7>=$P$4,$C$7<=$R$4),F17*$C$7*$T$4/100,IF(AND($C$7>=$P$3,$C$7<=$R$3),F17*$C$7*$T$3/100,IF($C$7>=$P$6,F17*$C$7*$T$6/100)))) -> 21 | H17: =((B17*5)+D17)/6 -> 1 | I17: =IF(AND($C$7>=$P$5,$C$7<=$R$5),H17*$C$7*$T$5/100,IF(AND($C$7>=$P$4,$C$7<=$R$4),H17*$C$7*$T$4/100,IF(AND($C$7>=$P$3,$C$7<=$R$3),H17*$C$7*$T$3/100,IF($C$7>=$P$6,H17*$C$7*$T$6/100)))) -> 21 | J17: =((B17*5)+D17+F17)/7 -> 1 | K17: =IF(AND($C$7>=$P$5,$C$7<=$R$5),J17*$C$7*$T$5/100,IF(AND($C$7>=$P$4,$C$7<=$R$4),J17*$C$7*$T$4/100,IF(AND($C$7>=$P$3,$C$7<=$R$3),J17*$C$7*$T$3/100,IF($C$7>=$P$6,J17*$C$7*$T$6/100)))) -> 21
A18: 5-6 | B18: 13 | C18: =IF(AND($C$7>=$P$5,$C$7<=$R$5),B18*$C$7*$T$5/100,IF(AND($C$7>=$P$4,$C$7<=$R$4),B18*$C$7*$T$4/100,IF(AND($C$7>=$P$3,$C$7<=$R$3),B18*$C$7*$T$3/100,IF($C$7>=$P$6,B18*$C$7*$T$6/100)))) -> 273 | D18: 3 | E18: =IF(AND($C$7>=$P$5,$C$7<=$R$5),D18*$C$7*$T$5/100,IF(AND($C$7>=$P$4,$C$7<=$R$4),D18*$C$7*$T$4/100,IF(AND($C$7>=$P$3,$C$7<=$R$3),D18*$C$7*$T$3/100,IF($C$7>=$P$6,D18*$C$7*$T$6/100)))) -> 63 | F18: 3 | G18: =IF(AND($C$7>=$P$5,$C$7<=$R$5),F18*$C$7*$T$5/100,IF(AND($C$7>=$P$4,$C$7<=$R$4),F18*$C$7*$T$4/100,IF(AND($C$7>=$P$3,$C$7<=$R$3),F18*$C$7*$T$3/100,IF($C$7>=$P$6,F18*$C$7*$T$6/100)))) -> 63 | H18: =((B18*5)+D18)/6 -> 11.333333 | I18: =IF(AND($C$7>=$P$5,$C$7<=$R$5),H18*$C$7*$T$5/100,IF(AND($C$7>=$P$4,$C$7<=$R$4),H18*$C$7*$T$4/100,IF(AND($C$7>=$P$3,$C$7<=$R$3),H18*$C$7*$T$3/100,IF($C$7>=$P$6,H18*$C$7*$T$6/100)))) -> 238 | J18: =((B18*5)+D18+F18)/7 -> 10.142857 | K18: =IF(AND($C$7>=$P$5,$C$7<=$R$5),J18*$C$7*$T$5/100,IF(AND($C$7>=$P$4,$C$7<=$R$4),J18*$C$7*$T$4/100,IF(AND($C$7>=$P$3,$C$7<=$R$3),J18*$C$7*$T$3/100,IF($C$7>=$P$6,J18*$C$7*$T$6/100)))) -> 213
A19: 6-7 | B19: 48 | C19: =IF(AND($C$7>=$P$5,$C$7<=$R$5),B19*$C$7*$T$5/100,IF(AND($C$7>=$P$4,$C$7<=$R$4),B19*$C$7*$T$4/100,IF(AND($C$7>=$P$3,$C$7<=$R$3),B19*$C$7*$T$3/100,IF($C$7>=$P$6,B19*$C$7*$T$6/100)))) -> 1008 | D19: 13 | E19: =IF(AND($C$7>=$P$5,$C$7<=$R$5),D19*$C$7*$T$5/100,IF(AND($C$7>=$P$4,$C$7<=$R$4),D19*$C$7*$T$4/100,IF(AND($C$7>=$P$3,$C$7<=$R$3),D19*$C$7*$T$3/100,IF($C$7>=$P$6,D19*$C$7*$T$6/100)))) -> 273 | F19: 6 | G19: =IF(AND($C$7>=$P$5,$C$7<=$R$5),F19*$C$7*$T$5/100,IF(AND($C$7>=$P$4,$C$7<=$R$4),F19*$C$7*$T$4/100,IF(AND($C$7>=$P$3,$C$7<=$R$3),F19*$C$7*$T$3/100,IF($C$7>=$P$6,F19*$C$7*$T$6/100)))) -> 126 | H19: =((B19*5)+D19)/6 -> 42.166667 | I19: =IF(AND($C$7>=$P$5,$C$7<=$R$5),H19*$C$7*$T$5/100,IF(AND($C$7>=$P$4,$C$7<=$R$4),H19*$C$7*$T$4/100,IF(AND($C$7>=$P$3,$C$7<=$R$3),H19*$C$7*$T$3/100,IF($C$7>=$P$6,H19*$C$7*$T$6/100)))) -> 885.5 | J19: =((B19*5)+D19+F19)/7 -> 37 | K19: =IF(AND($C$7>=$P$5,$C$7<=$R$5),J19*$C$7*$T$5/100,IF(AND($C$7>=$P$4,$C$7<=$R$4),J19*$C$7*$T$4/100,IF(AND($C$7>=$P$3,$C$7<=$R$3),J19*$C$7*$T$3/100,IF($C$7>=$P$6,J19*$C$7*$T$6/100)))) -> 777
A20: 7-8 | B20: 67 | C20: =IF(AND($C$7>=$P$5,$C$7<=$R$5),B20*$C$7*$T$5/100,IF(AND($C$7>=$P$4,$C$7<=$R$4),B20*$C$7*$T$4/100,IF(AND($C$7>=$P$3,$C$7<=$R$3),B20*$C$7*$T$3/100,IF($C$7>=$P$6,B20*$C$7*$T$6/100)))) -> 1407 | D20: 40 | E20: =IF(AND($C$7>=$P$5,$C$7<=$R$5),D20*$C$7*$T$5/100,IF(AND($C$7>=$P$4,$C$7<=$R$4),D20*$C$7*$T$4/100,IF(AND($C$7>=$P$3,$C$7<=$R$3),D20*$C$7*$T$3/100,IF($C$7>=$P$6,D20*$C$7*$T$6/100)))) -> 840 | F20: 13 | G20: =IF(AND($C$7>=$P$5,$C$7<=$R$5),F20*$C$7*$T$5/100,IF(AND($C$7>=$P$4,$C$7<=$R$4),F20*$C$7*$T$4/100,IF(AND($C$7>=$P$3,$C$7<=$R$3),F20*$C$7*$T$3/100,IF($C$7>=$P$6,F20*$C$7*$T$6/100)))) -> 273 | H20: =((B20*5)+D20)/6 -> 62.5 | I20: =IF(AND($C$7>=$P$5,$C$7<=$R$5),H20*$C$7*$T$5/100,IF(AND($C$7>=$P$4,$C$7<=$R$4),H20*$C$7*$T$4/100,IF(AND($C$7>=$P$3,$C$7<=$R$3),H20*$C$7*$T$3/100,IF($C$7>=$P$6,H20*$C$7*$T$6/100)))) -> 1312.5 | J20: =((B20*5)+D20+F20)/7 -> 55.428571 | K20: =IF(AND($C$7>=$P$5,$C$7<=$R$5),J20*$C$7*$T$5/100,IF(AND($C$7>=$P$4,$C$7<=$R$4),J20*$C$7*$T$4/100,IF(AND($C$7>=$P$3,$C$7<=$R$3),J20*$C$7*$T$3/100,IF($C$7>=$P$6,J20*$C$7*$T$6/100)))) -> 1164
A21: 8-9 | B21: 56 | C21: =IF(AND($C$7>=$P$5,$C$7<=$R$5),B21*$C$7*$T$5/100,IF(AND($C$7>=$P$4,$C$7<=$R$4),B21*$C$7*$T$4/100,IF(AND($C$7>=$P$3,$C$7<=$R$3),B21*$C$7*$T$3/100,IF($C$7>=$P$6,B21*$C$7*$T$6/100)))) -> 1176 | D21: 53 | E21: =IF(AND($C$7>=$P$5,$C$7<=$R$5),D21*$C$7*$T$5/100,IF(AND($C$7>=$P$4,$C$7<=$R$4),D21*$C$7*$T$4/100,IF(AND($C$7>=$P$3,$C$7<=$R$3),D21*$C$7*$T$3/100,IF($C$7>=$P$6,D21*$C$7*$T$6/100)))) -> 1113 | F21: 35 | G21: =IF(AND($C$7>=$P$5,$C$7<=$R$5),F21*$C$7*$T$5/100,IF(AND($C$7>=$P$4,$C$7<=$R$4),F21*$C$7*$T$4/100,IF(AND($C$7>=$P$3,$C$7<=$R$3),F21*$C$7*$T$3/100,IF($C$7>=$P$6,F21*$C$7*$T$6/100)))) -> 735 | H21: =((B21*5)+D21)/6 -> 55.5 | I21: =IF(AND($C$7>=$P$5,$C$7<=$R$5),H21*$C$7*$T$5/100,IF(AND($C$7>=$P$4,$C$7<=$R$4),H21*$C$7*$T$4/100,IF(AND($C$7>=$P$3,$C$7<=$R$3),H21*$C$7*$T$3/100,IF($C$7>=$P$6,H21*$C$7*$T$6/100)))) -> 1165.5 | J21: =((B21*5)+D21+F21)/7 -> 52.571429 | K21: =IF(AND($C$7>=$P$5,$C$7<=$R$5),J21*$C$7*$T$5/100,IF(AND($C$7>=$P$4,$C$7<=$R$4),J21*$C$7*$T$4/100,IF(AND($C$7>=$P$3,$C$7<=$R$3),J21*$C$7*$T$3/100,IF($C$7>=$P$6,J21*$C$7*$T$6/100)))) -> 1104
A22: 9-10 | B22: 43 | C22: =IF(AND($C$7>=$P$5,$C$7<=$R$5),B22*$C$7*$T$5/100,IF(AND($C$7>=$P$4,$C$7<=$R$4),B22*$C$7*$T$4/100,IF(AND($C$7>=$P$3,$C$7<=$R$3),B22*$C$7*$T$3/100,IF($C$7>=$P$6,B22*$C$7*$T$6/100)))) -> 903 | D22: 66 | E22: =IF(AND($C$7>=$P$5,$C$7<=$R$5),D22*$C$7*$T$5/100,IF(AND($C$7>=$P$4,$C$7<=$R$4),D22*$C$7*$T$4/100,IF(AND($C$7>=$P$3,$C$7<=$R$3),D22*$C$7*$T$3/100,IF($C$7>=$P$6,D22*$C$7*$T$6/100)))) -> 1386 | F22: 53 | G22: =IF(AND($C$7>=$P$5,$C$7<=$R$5),F22*$C$7*$T$5/100,IF(AND($C$7>=$P$4,$C$7<=$R$4),F22*$C$7*$T$4/100,IF(AND($C$7>=$P$3,$C$7<=$R$3),F22*$C$7*$T$3/100,IF($C$7>=$P$6,F22*$C$7*$T$6/100)))) -> 1113 | H22: =((B22*5)+D22)/6 -> 46.833333 | I22: =IF(AND($C$7>=$P$5,$C$7<=$R$5),H22*$C$7*$T$5/100,IF(AND($C$7>=$P$4,$C$7<=$R$4),H22*$C$7*$T$4/100,IF(AND($C$7>=$P$3,$C$7<=$R$3),H22*$C$7*$T$3/100,IF($C$7>=$P$6,H22*$C$7*$T$6/100)))) -> 983.5 | J22: =((B22*5)+D22+F22)/7 -> 47.714286 | K22: =IF(AND($C$7>=$P$5,$C$7<=$R$5),J22*$C$7*$T$5/100,IF(AND($C$7>=$P$4,$C$7<=$R$4),J22*$C$7*$T$4/100,IF(AND($C$7>=$P$3,$C$7<=$R$3),J22*$C$7*$T$3/100,IF($C$7>=$P$6,J22*$C$7*$T$6/100)))) -> 1002
A23: 10-11 | B23: 31 | C23: =IF(AND($C$7>=$P$5,$C$7<=$R$5),B23*$C$7*$T$5/100,IF(AND($C$7>=$P$4,$C$7<=$R$4),B23*$C$7*$T$4/100,IF(AND($C$7>=$P$3,$C$7<=$R$3),B23*$C$7*$T$3/100,IF($C$7>=$P$6,B23*$C$7*$T$6/100)))) -> 651 | D23: 71 | E23: =IF(AND($C$7>=$P$5,$C$7<=$R$5),D23*$C$7*$T$5/100,IF(AND($C$7>=$P$4,$C$7<=$R$4),D23*$C$7*$T$4/100,IF(AND($C$7>=$P$3,$C$7<=$R$3),D23*$C$7*$T$3/100,IF($C$7>=$P$6,D23*$C$7*$T$6/100)))) -> 1491 | F23: 41 | G23: =IF(AND($C$7>=$P$5,$C$7<=$R$5),F23*$C$7*$T$5/100,IF(AND($C$7>=$P$4,$C$7<=$R$4),F23*$C$7*$T$4/100,IF(AND($C$7>=$P$3,$C$7<=$R$3),F23*$C$7*$T$3/100,IF($C$7>=$P$6,F23*$C$7*$T$6/100)))) -> 861 | H23: =((B23*5)+D23)/6 -> 37.666667 | I23: =IF(AND($C$7>=$P$5,$C$7<=$R$5),H23*$C$7*$T$5/100,IF(AND($C$7>=$P$4,$C$7<=$R$4),H23*$C$7*$T$4/100,IF(AND($C$7>=$P$3,$C$7<=$R$3),H23*$C$7*$T$3/100,IF($C$7>=$P$6,H23*$C$7*$T$6/100)))) -> 791 | J23: =((B23*5)+D23+F23)/7 -> 38.142857 | K23: =IF(AND($C$7>=$P$5,$C$7<=$R$5),J23*$C$7*$T$5/100,IF(AND($C$7>=$P$4,$C$7<=$R$4),J23*$C$7*$T$4/100,IF(AND($C$7>=$P$3,$C$7<=$R$3),J23*$C$7*$T$3/100,IF($C$7>=$P$6,J23*$C$7*$T$6/100)))) -> 801
A24: 11-12 | B24: 30 | C24: =IF(AND($C$7>=$P$5,$C$7<=$R$5),B24*$C$7*$T$5/100,IF(AND($C$7>=$P$4,$C$7<=$R$4),B24*$C$7*$T$4/100,IF(AND($C$7>=$P$3,$C$7<=$R$3),B24*$C$7*$T$3/100,IF($C$7>=$P$6,B24*$C$7*$T$6/100)))) -> 630 | D24: 38 | E24: =IF(AND($C$7>=$P$5,$C$7<=$R$5),D24*$C$7*$T$5/100,IF(AND($C$7>=$P$4,$C$7<=$R$4),D24*$C$7*$T$4/100,IF(AND($C$7>=$P$3,$C$7<=$R$3),D24*$C$7*$T$3/100,IF($C$7>=$P$6,D24*$C$7*$T$6/100)))) -> 798 | F24: 37 | G24: =IF(AND($C$7>=$P$5,$C$7<=$R$5),F24*$C$7*$T$5/100,IF(AND($C$7>=$P$4,$C$7<=$R$4),F24*$C$7*$T$4/100,IF(AND($C$7>=$P$3,$C$7<=$R$3),F24*$C$7*$T$3/100,IF($C$7>=$P$6,F24*$C$7*$T$6/100)))) -> 777 | H24: =((B24*5)+D24)/6 -> 31.333333 | I24: =IF(AND($C$7>=$P$5,$C$7<=$R$5),H24*$C$7*$T$5/100,IF(AND($C$7>=$P$4,$C$7<=$R$4),H24*$C$7*$T$4/100,IF(AND($C$7>=$P$3,$C$7<=$R$3),H24*$C$7*$T$3/100,IF($C$7>=$P$6,H24*$C$7*$T$6/100)))) -> 658 | J24: =((B24*5)+D24+F24)/7 -> 32.142857 | K24: =IF(AND($C$7>=$P$5,$C$7<=$R$5),J24*$C$7*$T$5/100,IF(AND($C$7>=$P$4,$C$7<=$R$4),J24*$C$7*$T$4/100,IF(AND($C$7>=$P$3,$C$7<=$R$3),J24*$C$7*$T$3/100,IF($C$7>=$P$6,J24*$C$7*$T$6/100)))) -> 675
... A35: 22-23 | B35: 2 | C35: =IF(AND($C$7>=$P$5,$C$7<=$R$5),B35*$C$7*$T$5/100,IF(AND($C$7>=$P$4,$C$7<=$R$4),B35*$C$7*$T$4/100,IF(AND($C$7>=$P$3,$C$7<=$R$3),B35*$C$7*$T$3/100,IF($C$7>=$P$6,B35*$C$7*$T$6/100)))) -> 42 | D35: 1 | E35: =IF(AND($C$7>=$P$5,$C$7<=$R$5),D35*$C$7*$T$5/100,IF(AND($C$7>=$P$4,$C$7<=$R$4),D35*$C$7*$T$4/100,IF(AND($C$7>=$P$3,$C$7<=$R$3),D35*$C$7*$T$3/100,IF($C$7>=$P$6,D35*$C$7*$T$6/100)))) -> 21 | F35: 1 | G35: =IF(AND($C$7>=$P$5,$C$7<=$R$5),F35*$C$7*$T$5/100,IF(AND($C$7>=$P$4,$C$7<=$R$4),F35*$C$7*$T$4/100,IF(AND($C$7>=$P$3,$C$7<=$R$3),F35*$C$7*$T$3/100,IF($C$7>=$P$6,F35*$C$7*$T$6/100)))) -> 21 | H35: =((B35*5)+D35)/6 -> 1.8333333 | I35: =IF(AND($C$7>=$P$5,$C$7<=$R$5),H35*$C$7*$T$5/100,IF(AND($C$7>=$P$4,$C$7<=$R$4),H35*$C$7*$T$4/100,IF(AND($C$7>=$P$3,$C$7<=$R$3),H35*$C$7*$T$3/100,IF($C$7>=$P$6,H35*$C$7*$T$6/100)))) -> 38.5 | J35: =((B35*5)+D35+F35)/7 -> 1.7142857 | K35: =IF(AND($C$7>=$P$5,$C$7<=$R$5),J35*$C$7*$T$5/100,IF(AND($C$7>=$P$4,$C$7<=$R$4),J35*$C$7*$T$4/100,IF(AND($C$7>=$P$3,$C$7<=$R$3),J35*$C$7*$T$3/100,IF($C$7>=$P$6,J35*$C$7*$T$6/100)))) -> 36
A36: 23-24 | B36: 2 | C36: =IF(AND($C$7>=$P$5,$C$7<=$R$5),B36*$C$7*$T$5/100,IF(AND($C$7>=$P$4,$C$7<=$R$4),B36*$C$7*$T$4/100,IF(AND($C$7>=$P$3,$C$7<=$R$3),B36*$C$7*$T$3/100,IF($C$7>=$P$6,B36*$C$7*$T$6/100)))) -> 42 | D36: 1 | E36: =IF(AND($C$7>=$P$5,$C$7<=$R$5),D36*$C$7*$T$5/100,IF(AND($C$7>=$P$4,$C$7<=$R$4),D36*$C$7*$T$4/100,IF(AND($C$7>=$P$3,$C$7<=$R$3),D36*$C$7*$T$3/100,IF($C$7>=$P$6,D36*$C$7*$T$6/100)))) -> 21 | F36: 1 | G36: =F36*$C$7 -> 20 | H36: =((B36*5)+D36)/6 -> 1.8333333 | I36: =IF(AND($C$7>=$P$5,$C$7<=$R$5),H36*$C$7*$T$5/100,IF(AND($C$7>=$P$4,$C$7<=$R$4),H36*$C$7*$T$4/100,IF(AND($C$7>=$P$3,$C$7<=$R$3),H36*$C$7*$T$3/100,IF($C$7>=$P$6,H36*$C$7*$T$6/100)))) -> 38.5 | J36: =((B36*5)+D36+F36)/7 -> 1.7142857 | K36: =IF(AND($C$7>=$P$5,$C$7<=$R$5),J36*$C$7*$T$5/100,IF(AND($C$7>=$P$4,$C$7<=$R$4),J36*$C$7*$T$4/100,IF(AND($C$7>=$P$3,$C$7<=$R$3),J36*$C$7*$T$3/100,IF($C$7>=$P$6,J36*$C$7*$T$6/100)))) -> 36
A37: ø 06-18 | B37: =SUM(B19:B30)/12 -> 38 | C37: =IF(AND($C$7>=$P$5,$C$7<=$R$5),B37*$C$7*$T$5/100,IF(AND($C$7>=$P$4,$C$7<=$R$4),B37*$C$7*$T$4/100,IF(AND($C$7>=$P$3,$C$7<=$R$3),B37*$C$7*$T$3/100,IF($C$7>=$P$6,B37*$C$7*$T$6/100)))) -> 798 | D37: =SUM(D19:D30)/12 -> 35 | E37: =IF(AND($C$7>=$P$5,$C$7<=$R$5),D37*$C$7*$T$5/100,IF(AND($C$7>=$P$4,$C$7<=$R$4),D37*$C$7*$T$4/100,IF(AND($C$7>=$P$3,$C$7<=$R$3),D37*$C$7*$T$3/100,IF($C$7>=$P$6,D37*$C$7*$T$6/100)))) -> 735 | F37: =SUM(F19:F30)/12 -> 25 | G37: =IF(AND($C$7>=$P$5,$C$7<=$R$5),F37*$C$7*$T$5/100,IF(AND($C$7>=$P$4,$C$7<=$R$4),F37*$C$7*$T$4/100,IF(AND($C$7>=$P$3,$C$7<=$R$3),F37*$C$7*$T$3/100,IF($C$7>=$P$6,F37*$C$7*$T$6/100)))) -> 525 | H37: =SUM(H19:H30)/12 -> 37.5 | I37: =((5*C37)+E37)/6 -> 787.5 | J37: =SUM(J19:J30)/12 -> 35.714286 | K37: =((5*C37)+E37+G37)/7 -> 750
A38: ø 05-10 | B38: =SUM(B18:B22)/5 -> 45.4 | C38: =IF(AND($C$7>=$P$5,$C$7<=$R$5),B38*$C$7*$T$5/100,IF(AND($C$7>=$P$4,$C$7<=$R$4),B38*$C$7*$T$4/100,IF(AND($C$7>=$P$3,$C$7<=$R$3),B38*$C$7*$T$3/100,IF($C$7>=$P$6,B38*$C$7*$T$6/100)))) -> 953.4 | D38: =SUM(D18:D22)/5 -> 35 | E38: =IF(AND($C$7>=$P$5,$C$7<=$R$5),D38*$C$7*$T$5/100,IF(AND($C$7>=$P$4,$C$7<=$R$4),D38*$C$7*$T$4/100,IF(AND($C$7>=$P$3,$C$7<=$R$3),D38*$C$7*$T$3/100,IF($C$7>=$P$6,D38*$C$7*$T$6/100)))) -> 735 | F38: =SUM(F18:F22)/5 -> 22 | G38: =IF(AND($C$7>=$P$5,$C$7<=$R$5),F38*$C$7*$T$5/100,IF(AND($C$7>=$P$4,$C$7<=$R$4),F38*$C$7*$T$4/100,IF(AND($C$7>=$P$3,$C$7<=$R$3),F38*$C$7*$T$3/100,IF($C$7>=$P$6,F38*$C$7*$T$6/100)))) -> 462 | H38: =SUM(H18:H22)/5 -> 43.666667 | I38: =((5*C38)+E38)/6 -> 917 | J38: =SUM(J18:J22)/5 -> 40.571429 | K38: =((5*C38)+E38+G38)/7 -> 852
A39: ø 05-22 | B39: =SUM(B18:B34)/17 -> 30.058824 | C39: =IF(AND($C$7>=$P$5,$C$7<=$R$5),B39*$C$7*$T$5/100,IF(AND($C$7>=$P$4,$C$7<=$R$4),B39*$C$7*$T$4/100,IF(AND($C$7>=$P$3,$C$7<=$R$3),B39*$C$7*$T$3/100,IF($C$7>=$P$6,B39*$C$7*$T$6/100)))) -> 631.23529 | D39: =SUM(D18:D34)/17 -> 25.941176 | E39: =IF(AND($C$7>=$P$5,$C$7<=$R$5),D39*$C$7*$T$5/100,IF(AND($C$7>=$P$4,$C$7<=$R$4),D39*$C$7*$T$4/100,IF(AND($C$7>=$P$3,$C$7<=$R$3),D39*$C$7*$T$3/100,IF($C$7>=$P$6,D39*$C$7*$T$6/100)))) -> 544.76471 | F39: =SUM(F18:F34)/17 -> 18.823529 | G39: =IF(AND($C$7>=$P$5,$C$7<=$R$5),F39*$C$7*$T$5/100,IF(AND($C$7>=$P$4,$C$7<=$R$4),F39*$C$7*$T$4/100,IF(AND($C$7>=$P$3,$C$7<=$R$3),F39*$C$7*$T$3/100,IF($C$7>=$P$6,F39*$C$7*$T$6/100)))) -> 395.29412 | H39: =SUM(H18:H34)/17 -> 29.372549 | I39: =((5*C39)+E39)/6 -> 616.82353 | J39: =SUM(J18:J34)/17 -> 27.865546 | K39: =((5*C39)+E39+G39)/7 -> 585.17647
A40: ø 05-24 | B40: =SUM(B18:B36)/19 -> 27.105263 | C40: =IF(AND($C$7>=$P$5,$C$7<=$R$5),B40*$C$7*$T$5/100,IF(AND($C$7>=$P$4,$C$7<=$R$4),B40*$C$7*$T$4/100,IF(AND($C$7>=$P$3,$C$7<=$R$3),B40*$C$7*$T$3/100,IF($C$7>=$P$6,B40*$C$7*$T$6/100)))) -> 569.21053 | D40: =SUM(D18:D36)/19 -> 23.315789 | E40: =IF(AND($C$7>=$P$5,$C$7<=$R$5),D40*$C$7*$T$5/100,IF(AND($C$7>=$P$4,$C$7<=$R$4),D40*$C$7*$T$4/100,IF(AND($C$7>=$P$3,$C$7<=$R$3),D40*$C$7*$T$3/100,IF($C$7>=$P$6,D40*$C$7*$T$6/100)))) -> 489.63158 | F40: =SUM(F18:F36)/19 -> 16.947368 | G40: =IF(AND($C$7>=$P$5,$C$7<=$R$5),F40*$C$7*$T$5/100,IF(AND($C$7>=$P$4,$C$7<=$R$4),F40*$C$7*$T$4/100,IF(AND($C$7>=$P$3,$C$7<=$R$3),F40*$C$7*$T$3/100,IF($C$7>=$P$6,F40*$C$7*$T$6/100)))) -> 355.89474 | H40: =SUM(H18:H36)/19 -> 26.473684 | I40: =((5*C40)+E40)/6 -> 555.94737 | J40: =SUM(J18:J36)/19 -> 25.112782 | K40: =((5*C40)+E40+G40)/7 -> 527.36842
A41: ø 06-09 | B41: =SUM(B19:B21)/3 -> 57 | C41: =IF(AND($C$7>=$P$5,$C$7<=$R$5),B41*$C$7*$T$5/100,IF(AND($C$7>=$P$4,$C$7<=$R$4),B41*$C$7*$T$4/100,IF(AND($C$7>=$P$3,$C$7<=$R$3),B41*$C$7*$T$3/100,IF($C$7>=$P$6,B41*$C$7*$T$6/100)))) -> 1197 | D41: =SUM(D19:D21)/3 -> 35.333333 | E41: =IF(AND($C$7>=$P$5,$C$7<=$R$5),D41*$C$7*$T$5/100,IF(AND($C$7>=$P$4,$C$7<=$R$4),D41*$C$7*$T$4/100,IF(AND($C$7>=$P$3,$C$7<=$R$3),D41*$C$7*$T$3/100,IF($C$7>=$P$6,D41*$C$7*$T$6/100)))) -> 742 | F41: =SUM(F19:F21)/3 -> 18 | G41: =IF(AND($C$7>=$P$5,$C$7<=$R$5),F41*$C$7*$T$5/100,IF(AND($C$7>=$P$4,$C$7<=$R$4),F41*$C$7*$T$4/100,IF(AND($C$7>=$P$3,$C$7<=$R$3),F41*$C$7*$T$3/100,IF($C$7>=$P$6,F41*$C$7*$T$6/100)))) -> 378 | H41: =SUM(H19:H21)/3 -> 53.388889 | I41: =((5*C41)+E41)/6 -> 1121.1667 | J41: =SUM(J19:J21)/3 -> 48.333333 | K41: =((5*C41)+E41+G41)/7 -> 1015
A42: ø 06-10 | B42: =SUM(B19:B22)/4 -> 53.5 | C42: =IF(AND($C$7>=$P$5,$C$7<=$R$5),B42*$C$7*$T$5/100,IF(AND($C$7>=$P$4,$C$7<=$R$4),B42*$C$7*$T$4/100,IF(AND($C$7>=$P$3,$C$7<=$R$3),B42*$C$7*$T$3/100,IF($C$7>=$P$6,B42*$C$7*$T$6/100)))) -> 1123.5 | D42: =SUM(D19:D22)/4 -> 43 | E42: =IF(AND($C$7>=$P$5,$C$7<=$R$5),D42*$C$7*$T$5/100,IF(AND($C$7>=$P$4,$C$7<=$R$4),D42*$C$7*$T$4/100,IF(AND($C$7>=$P$3,$C$7<=$R$3),D42*$C$7*$T$3/100,IF($C$7>=$P$6,D42*$C$7*$T$6/100)))) -> 903 | F42: =SUM(F19:F22)/4 -> 26.75 | G42: =IF(AND($C$7>=$P$5,$C$7<=$R$5),F42*$C$7*$T$5/100,IF(AND($C$7>=$P$4,$C$7<=$R$4),F42*$C$7*$T$4/100,IF(AND($C$7>=$P$3,$C$7<=$R$3),F42*$C$7*$T$3/100,IF($C$7>=$P$6,F42*$C$7*$T$6/100)))) -> 561.75 | H42: =SUM(H19:H22)/4 -> 51.75 | I42: =((5*C42)+E42)/6 -> 1086.75 | J42: =SUM(J19:J22)/4 -> 48.178571 | K42: =((5*C42)+E42+G42)/7 -> 1011.75
A43: ø 06-14 | B43: =SUM(B19:B26)/8 -> 41.875 | C43: =IF(AND($C$7>=$P$5,$C$7<=$R$5),B43*$C$7*$T$5/100,IF(AND($C$7>=$P$4,$C$7<=$R$4),B43*$C$7*$T$4/100,IF(AND($C$7>=$P$3,$C$7<=$R$3),B43*$C$7*$T$3/100,IF($C$7>=$P$6,B43*$C$7*$T$6/100)))) -> 879.375 | D43: =SUM(D19:D26)/8 -> 43 | E43: =IF(AND($C$7>=$P$5,$C$7<=$R$5),D43*$C$7*$T$5/100,IF(AND($C$7>=$P$4,$C$7<=$R$4),D43*$C$7*$T$4/100,IF(AND($C$7>=$P$3,$C$7<=$R$3),D43*$C$7*$T$3/100,IF($C$7>=$P$6,D43*$C$7*$T$6/100)))) -> 903 | F43: =SUM(F19:F26)/8 -> 28.25 | G43: =IF(AND($C$7>=$P$5,$C$7<=$R$5),F43*$C$7*$T$5/100,IF(AND($C$7>=$P$4,$C$7<=$R$4),F43*$C$7*$T$4/100,IF(AND($C$7>=$P$3,$C$7<=$R$3),F43*$C$7*$T$3/100,IF($C$7>=$P$6,F43*$C$7*$T$6/100)))) -> 593.25 | H43: =SUM(H19:H26)/8 -> 42.0625 | I43: =((5*C43)+E43)/6 -> 883.3125 | J43: =SUM(J19:J26)/8 -> 40.089286 | K43: =((5*C43)+E43+G43)/7 -> 841.875
A44: ø 06-19 | B44: =SUM(B19:B31)/13 -> 36.846154 | C44: =IF(AND($C$7>=$P$5,$C$7<=$R$5),B44*$C$7*$T$5/100,IF(AND($C$7>=$P$4,$C$7<=$R$4),B44*$C$7*$T$4/100,IF(AND($C$7>=$P$3,$C$7<=$R$3),B44*$C$7*$T$3/100,IF($C$7>=$P$6,B44*$C$7*$T$6/100)))) -> 773.76923 | D44: =SUM(D19:D31)/13 -> 33 | E44: =IF(AND($C$7>=$P$5,$C$7<=$R$5),D44*$C$7*$T$5/100,IF(AND($C$7>=$P$4,$C$7<=$R$4),D44*$C$7*$T$4/100,IF(AND($C$7>=$P$3,$C$7<=$R$3),D44*$C$7*$T$3/100,IF($C$7>=$P$6,D44*$C$7*$T$6/100)))) -> 693 | F44: =SUM(F19:F31)/13 -> 23.692308 | G44: =IF(AND($C$7>=$P$5,$C$7<=$R$5),F44*$C$7*$T$5/100,IF(AND($C$7>=$P$4,$C$7<=$R$4),F44*$C$7*$T$4/100,IF(AND($C$7>=$P$3,$C$7<=$R$3),F44*$C$7*$T$3/100,IF($C$7>=$P$6,F44*$C$7*$T$6/100)))) -> 497.53846 | H44: =SUM(H19:H31)/13 -> 36.205128 | I44: =((5*C44)+E44)/6 -> 760.30769 | J44: =SUM(J19:J31)/13 -> 34.417582 | K44: =((5*C44)+E44+G44)/7 -> 722.76923
A45: ø 06-20 | B45: =SUM(B19:B32)/14 -> 34.857143 | C45: =IF(AND($C$7>=$P$5,$C$7<=$R$5),B45*$C$7*$T$5/100,IF(AND($C$7>=$P$4,$C$7<=$R$4),B45*$C$7*$T$4/100,IF(AND($C$7>=$P$3,$C$7<=$R$3),B45*$C$7*$T$3/100,IF($C$7>=$P$6,B45*$C$7*$T$6/100)))) -> 732 | D45: =SUM(D19:D32)/14 -> 31.071429 | E45: =IF(AND($C$7>=$P$5,$C$7<=$R$5),D45*$C$7*$T$5/100,IF(AND($C$7>=$P$4,$C$7<=$R$4),D45*$C$7*$T$4/100,IF(AND($C$7>=$P$3,$C$7<=$R$3),D45*$C$7*$T$3/100,IF($C$7>=$P$6,D45*$C$7*$T$6/100)))) -> 652.5 | F45: =SUM(F19:F32)/14 -> 22.357143 | G45: =IF(AND($C$7>=$P$5,$C$7<=$R$5),F45*$C$7*$T$5/100,IF(AND($C$7>=$P$4,$C$7<=$R$4),F45*$C$7*$T$4/100,IF(AND($C$7>=$P$3,$C$7<=$R$3),F45*$C$7*$T$3/100,IF($C$7>=$P$6,F45*$C$7*$T$6/100)))) -> 469.5 | H45: =SUM(H19:H32)/14 -> 34.22619 | I45: =((5*C45)+E45)/6 -> 718.75 | J45: =SUM(J19:J32)/14 -> 32.530612 | K45: =((5*C45)+E45+G45)/7 -> 683.14286
A46: ø 06-22 | B46: =SUM(B19:B34)/16 -> 31.125 | C46: =IF(AND($C$7>=$P$5,$C$7<=$R$5),B46*$C$7*$T$5/100,IF(AND($C$7>=$P$4,$C$7<=$R$4),B46*$C$7*$T$4/100,IF(AND($C$7>=$P$3,$C$7<=$R$3),B46*$C$7*$T$3/100,IF($C$7>=$P$6,B46*$C$7*$T$6/100)))) -> 653.625 | D46: =SUM(D19:D34)/16 -> 27.375 | E46: =IF(AND($C$7>=$P$5,$C$7<=$R$5),D46*$C$7*$T$5/100,IF(AND($C$7>=$P$4,$C$7<=$R$4),D46*$C$7*$T$4/100,IF(AND($C$7>=$P$3,$C$7<=$R$3),D46*$C$7*$T$3/100,IF($C$7>=$P$6,D46*$C$7*$T$6/100)))) -> 574.875 | F46: =SUM(F19:F34)/16 -> 19.8125 | G46: =IF(AND($C$7>=$P$5,$C$7<=$R$5),F46*$C$7*$T$5/100,IF(AND($C$7>=$P$4,$C$7<=$R$4),F46*$C$7*$T$4/100,IF(AND($C$7>=$P$3,$C$7<=$R$3),F46*$C$7*$T$3/100,IF($C$7>=$P$6,F46*$C$7*$T$6/100)))) -> 416.0625 | H46: =SUM(H19:H34)/16 -> 30.5 | I46: =((5*C46)+E46)/6 -> 640.5 | J46: =SUM(J19:J34)/16 -> 28.973214 | K46: =((5*C46)+E46+G46)/7 -> 608.4375
A47: ø 06-24 | B47: =SUM(B19:B36)/18 -> 27.888889 | C47: =IF(AND($C$7>=$P$5,$C$7<=$R$5),B47*$C$7*$T$5/100,IF(AND($C$7>=$P$4,$C$7<=$R$4),B47*$C$7*$T$4/100,IF(AND($C$7>=$P$3,$C$7<=$R$3),B47*$C$7*$T$3/100,IF($C$7>=$P$6,B47*$C$7*$T$6/100)))) -> 585.66667 | D47: =SUM(D19:D36)/18 -> 24.444444 | E47: =IF(AND($C$7>=$P$5,$C$7<=$R$5),D47*$C$7*$T$5/100,IF(AND($C$7>=$P$4,$C$7<=$R$4),D47*$C$7*$T$4/100,IF(AND($C$7>=$P$3,$C$7<=$R$3),D47*$C$7*$T$3/100,IF($C$7>=$P$6,D47*$C$7*$T$6/100)))) -> 513.33333 | F47: =SUM(F19:F36)/18 -> 17.722222 | G47: =IF(AND($C$7>=$P$5,$C$7<=$R$5),F47*$C$7*$T$5/100,IF(AND($C$7>=$P$4,$C$7<=$R$4),F47*$C$7*$T$4/100,IF(AND($C$7>=$P$3,$C$7<=$R$3),F47*$C$7*$T$3/100,IF($C$7>=$P$6,F47*$C$7*$T$6/100)))) -> 372.16667 | H47: =SUM(H19:H36)/18 -> 27.314815 | I47: =((5*C47)+E47)/6 -> 573.61111 | J47: =SUM(J19:J36)/18 -> 25.944444 | K47: =((5*C47)+E47+G47)/7 -> 544.83333
A48: ø 07-24 | B48: =SUM(B20:B36)/17 -> 26.705882 | C48: =IF(AND($C$7>=$P$5,$C$7<=$R$5),B48*$C$7*$T$5/100,IF(AND($C$7>=$P$4,$C$7<=$R$4),B48*$C$7*$T$4/100,IF(AND($C$7>=$P$3,$C$7<=$R$3),B48*$C$7*$T$3/100,IF($C$7>=$P$6,B48*$C$7*$T$6/100)))) -> 560.82353 | D48: =SUM(D20:D36)/17 -> 25.117647 | E48: =IF(AND($C$7>=$P$5,$C$7<=$R$5),D48*$C$7*$T$5/100,IF(AND($C$7>=$P$4,$C$7<=$R$4),D48*$C$7*$T$4/100,IF(AND($C$7>=$P$3,$C$7<=$R$3),D48*$C$7*$T$3/100,IF($C$7>=$P$6,D48*$C$7*$T$6/100)))) -> 527.47059 | F48: =SUM(F20:F36)/17 -> 18.411765 | G48: =IF(AND($C$7>=$P$5,$C$7<=$R$5),F48*$C$7*$T$5/100,IF(AND($C$7>=$P$4,$C$7<=$R$4),F48*$C$7*$T$4/100,IF(AND($C$7>=$P$3,$C$7<=$R$3),F48*$C$7*$T$3/100,IF($C$7>=$P$6,F48*$C$7*$T$6/100)))) -> 386.64706 | H48: =SUM(H20:H36)/17 -> 26.441176 | I48: =((5*C48)+E48)/6 -> 555.26471 | J48: =SUM(J20:J36)/17 -> 25.294118 | K48: =((5*C48)+E48+G48)/7 -> 531.17647
A49: ø 08-13 | B49: =SUM(B21:B25)/5 -> 38 | C49: =IF(AND($C$7>=$P$5,$C$7<=$R$5),B49*$C$7*$T$5/100,IF(AND($C$7>=$P$4,$C$7<=$R$4),B49*$C$7*$T$4/100,IF(AND($C$7>=$P$3,$C$7<=$R$3),B49*$C$7*$T$3/100,IF($C$7>=$P$6,B49*$C$7*$T$6/100)))) -> 798 | D49: =SUM(D21:D25)/5 -> 53.2 | E49: =IF(AND($C$7>=$P$5,$C$7<=$R$5),D49*$C$7*$T$5/100,IF(AND($C$7>=$P$4,$C$7<=$R$4),D49*$C$7*$T$4/100,IF(AND($C$7>=$P$3,$C$7<=$R$3),D49*$C$7*$T$3/100,IF($C$7>=$P$6,D49*$C$7*$T$6/100)))) -> 1117.2 | F49: =SUM(F21:F25)/5 -> 37.8 | G49: =IF(AND($C$7>=$P$5,$C$7<=$R$5),F49*$C$7*$T$5/100,IF(AND($C$7>=$P$4,$C$7<=$R$4),F49*$C$7*$T$4/100,IF(AND($C$7>=$P$3,$C$7<=$R$3),F49*$C$7*$T$3/100,IF($C$7>=$P$6,F49*$C$7*$T$6/100)))) -> 793.8 | H49: =SUM(H21:H25)/5 -> 40.533333 | I49: =((5*C49)+E49)/6 -> 851.2 | J49: =SUM(J21:J25)/5 -> 40.142857 | K49: =((5*C49)+E49+G49)/7 -> 843
A50: ø 08-18 | B50: =SUM(B21:B30)/10 -> 34.1 | C50: =IF(AND($C$7>=$P$5,$C$7<=$R$5),B50*$C$7*$T$5/100,IF(AND($C$7>=$P$4,$C$7<=$R$4),B50*$C$7*$T$4/100,IF(AND($C$7>=$P$3,$C$7<=$R$3),B50*$C$7*$T$3/100,IF($C$7>=$P$6,B50*$C$7*$T$6/100)))) -> 716.1 | D50: =SUM(D21:D30)/10 -> 36.7 | E50: =IF(AND($C$7>=$P$5,$C$7<=$R$5),D50*$C$7*$T$5/100,IF(AND($C$7>=$P$4,$C$7<=$R$4),D50*$C$7*$T$4/100,IF(AND($C$7>=$P$3,$C$7<=$R$3),D50*$C$7*$T$3/100,IF($C$7>=$P$6,D50*$C$7*$T$6/100)))) -> 770.7 | F50: =SUM(F21:F30)/10 -> 28.1 | G50: =IF(AND($C$7>=$P$5,$C$7<=$R$5),F50*$C$7*$T$5/100,IF(AND($C$7>=$P$4,$C$7<=$R$4),F50*$C$7*$T$4/100,IF(AND($C$7>=$P$3,$C$7<=$R$3),F50*$C$7*$T$3/100,IF($C$7>=$P$6,F50*$C$7*$T$6/100)))) -> 590.1 | H50: =SUM(H21:H30)/10 -> 34.533333 | I50: =((5*C50)+E50)/6 -> 725.2 | J50: =SUM(J21:J30)/10 -> 33.614286 | K50: =((5*C50)+E50+G50)/7 -> 705.9
...

Sheet PlanerRHH
A4: Preise 2026 (gültig ab 1. Januar 2026)
B6: Kunde: | I6: Spots Gesamt | M6: =B41+F41+J41 -> 0 | R6: Spotlängenbonus | V6: Index | BE6: =WEEKDAY(AP7,2) -> 6 | BF6: =DAYS360(AP7,AP8)+1 -> 1
B7: Produkt: | I7: Sekunden Ges. | M7: =G9*M6 -> 0 | R7: 1 | S7: - | T7: 15 | U7: Sek. | V7: 110
B8: Agentur: | I8: Euro | M8: =E41+I41+M41 -> 0 | R8: 16 | S8: - | T8: 24 | U8: Sek. | V8: 105
B9: Spotlänge in Sekunden: | G9: 10 | I9: Rabatt | L9: 0.05 | M9: =M8*L9 -> 0 | R9: 25 | S9: - | T9: 34 | U9: Sek. | V9: 100
B10: Aufschlag in % | G10: 50 | I10: Netto 1 | M10: =M8-M9 -> 0 | R10: 35 | S10: - | T10: 99 | U10: Sek. | V10: 95
I11: AE | L11: 0.15 | M11: =M10*L11 -> 0
I12: Netto 2 | M12: =M10-M11 -> 0
A14: UHRZEIT | B14: MONTAG - FREITAG | F14: SAMSTAG | J14: SONNTAG | N14: WOCHE 1 | U14: WOCHE 2 | AB14: WOCHE 3 | AI14: WOCHE 4 | AP14: WOCHE 5 | AW14: WOCHE 6
C15: Euro/ | D15: Euro/ | E15: Euro/ | G15: Euro/ | H15: Euro/ | I15: Euro/ | K15: Euro/ | L15: Euro/ | M15: Euro/ | N15: Mo | O15: Di | P15: Mi | Q15: Do | R15: Fr | S15: Sa | T15: So | U15: Mo | V15: Di | W15: Mi | X15: Do | Y15: Fr | Z15: Sa | AA15: So | AB15: Mo | AC15: Di | AD15: Mi | AE15: Do | AF15: Fr | AG15: Sa | AH15: So | AI15: Mo | AJ15: Di | AK15: Mi | AL15: Do | AM15: Fr | AN15: Sa | AO15: So | AP15: Mo | AQ15: Di | AR15: Mi | AS15: Do | AT15: Fr | AU15: Sa | AV15: So | AW15: Mo | AX15: Di | AY15: Mi | AZ15: Do | BA15: Fr | BB15: Sa | BC15: So
B16: Anz. | C16: Sek. | D16: Spot | E16: ges. | F16: Anz. | G16: Sek. | H16: Spot | I16: ges. | J16: Anz. | K16: Sek. | L16: Spot | M16: ges. | N16: =IF(BE6=1,1,"") | O16: =IF($BE6=2,1,IF($BE6=1,2,"")) | P16: =IF($BE6=3,1,IF($BE6=2,2,IF(BE6=1,3,""))) | Q16: =IF($BE6=4,1,IF($BE6=3,2,IF(BE6=2,3,IF(BE6=1,4,"")))) | R16: =IF($BE6=5,1,IF($BE6=4,2,IF(BE6=3,3,IF(BE6=2,4,IF(BE6=1,5,"")))))
A17: 0-1 Uhr | B17: =SUM(N17:R17,U17:Y17,AB17:AF17,AI17:AM17,AP17:AT17,AW17:BA17) -> 0 | C17: ='Preise RHH'!B13 -> 1 | D17: =IF(AND($G$9>=$R$9,$G$9<=$T$9),C17*$G$9*$V$9/100,IF(AND($G$9>=$R$8,$G$9<=$T$8),C17*$G$9*$V$8/100,IF(AND($G$9>=$R$7,$G$9<=$T$7),C17*$G$9*$V$7/100,IF($G$9>=$R$10,C17*$G$9*$V$10/100)))) -> 11 | E17: =B17*D17*(100+$G$10)/100 -> 0 | F17: =SUM(S17,Z17,AG17,AN17,AU17,BB17) -> 0 | G17: ='Preise RHH'!D13 -> 1 | H17: =IF(AND($G$9>=$R$9,$G$9<=$T$9),G17*$G$9*$V$9/100,IF(AND($G$9>=$R$8,$G$9<=$T$8),G17*$G$9*$V$8/100,IF(AND($G$9>=$R$7,$G$9<=$T$7),G17*$G$9*$V$7/100,IF($G$9>=$R$10,G17*$G$9*$V$10/100)))) -> 11 | I17: =F17*H17*(100+$G$10)/100 -> 0 | J17: =SUM(T17,AA17,AH17,AO17,AV17,BC17) -> 0 | K17: ='Preise RHH'!F13 -> 1 | L17: =IF(AND($G$9>=$R$9,$G$9<=$T$9),K17*$G$9*$V$9/100,IF(AND($G$9>=$R$8,$G$9<=$T$8),K17*$G$9*$V$8/100,IF(AND($G$9>=$R$7,$G$9<=$T$7),K17*$G$9*$V$7/100,IF($G$9>=$R$10,K17*$G$9*$V$10/100)))) -> 11 | M17: =J17*L17*(100+$G$10)/100 -> 0
A18: 1-2 Uhr | B18: =SUM(N18:R18,U18:Y18,AB18:AF18,AI18:AM18,AP18:AT18,AW18:BA18) -> 0 | C18: ='Preise RHH'!B14 -> 1 | D18: =IF(AND($G$9>=$R$9,$G$9<=$T$9),C18*$G$9*$V$9/100,IF(AND($G$9>=$R$8,$G$9<=$T$8),C18*$G$9*$V$8/100,IF(AND($G$9>=$R$7,$G$9<=$T$7),C18*$G$9*$V$7/100,IF($G$9>=$R$10,C18*$G$9*$V$10/100)))) -> 11 | E18: =B18*D18*(100+$G$10)/100 -> 0 | F18: =SUM(S18,Z18,AG18,AN18,AU18,BB18) -> 0 | G18: ='Preise RHH'!D14 -> 1 | H18: =IF(AND($G$9>=$R$9,$G$9<=$T$9),G18*$G$9*$V$9/100,IF(AND($G$9>=$R$8,$G$9<=$T$8),G18*$G$9*$V$8/100,IF(AND($G$9>=$R$7,$G$9<=$T$7),G18*$G$9*$V$7/100,IF($G$9>=$R$10,G18*$G$9*$V$10/100)))) -> 11 | I18: =F18*H18*(100+$G$10)/100 -> 0 | J18: =SUM(T18,AA18,AH18,AO18,AV18,BC18) -> 0 | K18: ='Preise RHH'!F14 -> 1 | L18: =IF(AND($G$9>=$R$9,$G$9<=$T$9),K18*$G$9*$V$9/100,IF(AND($G$9>=$R$8,$G$9<=$T$8),K18*$G$9*$V$8/100,IF(AND($G$9>=$R$7,$G$9<=$T$7),K18*$G$9*$V$7/100,IF($G$9>=$R$10,K18*$G$9*$V$10/100)))) -> 11 | M18: =J18*L18*(100+$G$10)/100 -> 0
A19: 2-3 Uhr | B19: =SUM(N19:R19,U19:Y19,AB19:AF19,AI19:AM19,AP19:AT19,AW19:BA19) -> 0 | C19: ='Preise RHH'!B15 -> 1 | D19: =IF(AND($G$9>=$R$9,$G$9<=$T$9),C19*$G$9*$V$9/100,IF(AND($G$9>=$R$8,$G$9<=$T$8),C19*$G$9*$V$8/100,IF(AND($G$9>=$R$7,$G$9<=$T$7),C19*$G$9*$V$7/100,IF($G$9>=$R$10,C19*$G$9*$V$10/100)))) -> 11 | E19: =B19*D19*(100+$G$10)/100 -> 0 | F19: =SUM(S19,Z19,AG19,AN19,AU19,BB19) -> 0 | G19: ='Preise RHH'!D15 -> 1 | H19: =IF(AND($G$9>=$R$9,$G$9<=$T$9),G19*$G$9*$V$9/100,IF(AND($G$9>=$R$8,$G$9<=$T$8),G19*$G$9*$V$8/100,IF(AND($G$9>=$R$7,$G$9<=$T$7),G19*$G$9*$V$7/100,IF($G$9>=$R$10,G19*$G$9*$V$10/100)))) -> 11 | I19: =F19*H19*(100+$G$10)/100 -> 0 | J19: =SUM(T19,AA19,AH19,AO19,AV19,BC19) -> 0 | K19: ='Preise RHH'!F15 -> 1 | L19: =IF(AND($G$9>=$R$9,$G$9<=$T$9),K19*$G$9*$V$9/100,IF(AND($G$9>=$R$8,$G$9<=$T$8),K19*$G$9*$V$8/100,IF(AND($G$9>=$R$7,$G$9<=$T$7),K19*$G$9*$V$7/100,IF($G$9>=$R$10,K19*$G$9*$V$10/100)))) -> 11 | M19: =J19*L19*(100+$G$10)/100 -> 0
A20: 3-4 Uhr | B20: =SUM(N20:R20,U20:Y20,AB20:AF20,AI20:AM20,AP20:AT20,AW20:BA20) -> 0 | C20: ='Preise RHH'!B16 -> 1 | D20: =IF(AND($G$9>=$R$9,$G$9<=$T$9),C20*$G$9*$V$9/100,IF(AND($G$9>=$R$8,$G$9<=$T$8),C20*$G$9*$V$8/100,IF(AND($G$9>=$R$7,$G$9<=$T$7),C20*$G$9*$V$7/100,IF($G$9>=$R$10,C20*$G$9*$V$10/100)))) -> 11 | E20: =B20*D20*(100+$G$10)/100 -> 0 | F20: =SUM(S20,Z20,AG20,AN20,AU20,BB20) -> 0 | G20: ='Preise RHH'!D16 -> 1 | H20: =IF(AND($G$9>=$R$9,$G$9<=$T$9),G20*$G$9*$V$9/100,IF(AND($G$9>=$R$8,$G$9<=$T$8),G20*$G$9*$V$8/100,IF(AND($G$9>=$R$7,$G$9<=$T$7),G20*$G$9*$V$7/100,IF($G$9>=$R$10,G20*$G$9*$V$10/100)))) -> 11 | I20: =F20*H20*(100+$G$10)/100 -> 0 | J20: =SUM(T20,AA20,AH20,AO20,AV20,BC20) -> 0 | K20: ='Preise RHH'!F16 -> 1 | L20: =IF(AND($G$9>=$R$9,$G$9<=$T$9),K20*$G$9*$V$9/100,IF(AND($G$9>=$R$8,$G$9<=$T$8),K20*$G$9*$V$8/100,IF(AND($G$9>=$R$7,$G$9<=$T$7),K20*$G$9*$V$7/100,IF($G$9>=$R$10,K20*$G$9*$V$10/100)))) -> 11 | M20: =J20*L20*(100+$G$10)/100 -> 0
A21: 4-5 Uhr | B21: =SUM(N21:R21,U21:Y21,AB21:AF21,AI21:AM21,AP21:AT21,AW21:BA21) -> 0 | C21: ='Preise RHH'!B17 -> 1 | D21: =IF(AND($G$9>=$R$9,$G$9<=$T$9),C21*$G$9*$V$9/100,IF(AND($G$9>=$R$8,$G$9<=$T$8),C21*$G$9*$V$8/100,IF(AND($G$9>=$R$7,$G$9<=$T$7),C21*$G$9*$V$7/100,IF($G$9>=$R$10,C21*$G$9*$V$10/100)))) -> 11 | E21: =B21*D21*(100+$G$10)/100 -> 0 | F21: =SUM(S21,Z21,AG21,AN21,AU21,BB21) -> 0 | G21: ='Preise RHH'!D17 -> 1 | H21: =IF(AND($G$9>=$R$9,$G$9<=$T$9),G21*$G$9*$V$9/100,IF(AND($G$9>=$R$8,$G$9<=$T$8),G21*$G$9*$V$8/100,IF(AND($G$9>=$R$7,$G$9<=$T$7),G21*$G$9*$V$7/100,IF($G$9>=$R$10,G21*$G$9*$V$10/100)))) -> 11 | I21: =F21*H21*(100+$G$10)/100 -> 0 | J21: =SUM(T21,AA21,AH21,AO21,AV21,BC21) -> 0 | K21: ='Preise RHH'!F17 -> 1 | L21: =IF(AND($G$9>=$R$9,$G$9<=$T$9),K21*$G$9*$V$9/100,IF(AND($G$9>=$R$8,$G$9<=$T$8),K21*$G$9*$V$8/100,IF(AND($G$9>=$R$7,$G$9<=$T$7),K21*$G$9*$V$7/100,IF($G$9>=$R$10,K21*$G$9*$V$10/100)))) -> 11 | M21: =J21*L21*(100+$G$10)/100 -> 0
A22: 5-6 Uhr | B22: =SUM(N22:R22,U22:Y22,AB22:AF22,AI22:AM22,AP22:AT22,AW22:BA22) -> 0 | C22: ='Preise RHH'!B18 -> 13 | D22: =IF(AND($G$9>=$R$9,$G$9<=$T$9),C22*$G$9*$V$9/100,IF(AND($G$9>=$R$8,$G$9<=$T$8),C22*$G$9*$V$8/100,IF(AND($G$9>=$R$7,$G$9<=$T$7),C22*$G$9*$V$7/100,IF($G$9>=$R$10,C22*$G$9*$V$10/100)))) -> 143 | E22: =B22*D22*(100+$G$10)/100 -> 0 | F22: =SUM(S22,Z22,AG22,AN22,AU22,BB22) -> 0 | G22: ='Preise RHH'!D18 -> 3 | H22: =IF(AND($G$9>=$R$9,$G$9<=$T$9),G22*$G$9*$V$9/100,IF(AND($G$9>=$R$8,$G$9<=$T$8),G22*$G$9*$V$8/100,IF(AND($G$9>=$R$7,$G$9<=$T$7),G22*$G$9*$V$7/100,IF($G$9>=$R$10,G22*$G$9*$V$10/100)))) -> 33 | I22: =F22*H22*(100+$G$10)/100 -> 0 | J22: =SUM(T22,AA22,AH22,AO22,AV22,BC22) -> 0 | K22: ='Preise RHH'!F18 -> 3 | L22: =IF(AND($G$9>=$R$9,$G$9<=$T$9),K22*$G$9*$V$9/100,IF(AND($G$9>=$R$8,$G$9<=$T$8),K22*$G$9*$V$8/100,IF(AND($G$9>=$R$7,$G$9<=$T$7),K22*$G$9*$V$7/100,IF($G$9>=$R$10,K22*$G$9*$V$10/100)))) -> 33 | M22: =J22*L22*(100+$G$10)/100 -> 0 | BF22: =IF($AJ7<6000,0,0.025) -> 0
A23: 6-7 Uhr | B23: =SUM(N23:R23,U23:Y23,AB23:AF23,AI23:AM23,AP23:AT23,AW23:BA23) -> 0 | C23: ='Preise RHH'!B19 -> 48 | D23: =IF(AND($G$9>=$R$9,$G$9<=$T$9),C23*$G$9*$V$9/100,IF(AND($G$9>=$R$8,$G$9<=$T$8),C23*$G$9*$V$8/100,IF(AND($G$9>=$R$7,$G$9<=$T$7),C23*$G$9*$V$7/100,IF($G$9>=$R$10,C23*$G$9*$V$10/100)))) -> 528 | E23: =B23*D23*(100+$G$10)/100 -> 0 | F23: =SUM(S23,Z23,AG23,AN23,AU23,BB23) -> 0 | G23: ='Preise RHH'!D19 -> 13 | H23: =IF(AND($G$9>=$R$9,$G$9<=$T$9),G23*$G$9*$V$9/100,IF(AND($G$9>=$R$8,$G$9<=$T$8),G23*$G$9*$V$8/100,IF(AND($G$9>=$R$7,$G$9<=$T$7),G23*$G$9*$V$7/100,IF($G$9>=$R$10,G23*$G$9*$V$10/100)))) -> 143 | I23: =F23*H23*(100+$G$10)/100 -> 0 | J23: =SUM(T23,AA23,AH23,AO23,AV23,BC23) -> 0 | K23: ='Preise RHH'!F19 -> 6 | L23: =IF(AND($G$9>=$R$9,$G$9<=$T$9),K23*$G$9*$V$9/100,IF(AND($G$9>=$R$8,$G$9<=$T$8),K23*$G$9*$V$8/100,IF(AND($G$9>=$R$7,$G$9<=$T$7),K23*$G$9*$V$7/100,IF($G$9>=$R$10,K23*$G$9*$V$10/100)))) -> 66 | M23: =J23*L23*(100+$G$10)/100 -> 0 | BF23: =IF($AJ7<9000,0,0.025) -> 0
A24: 7-8 Uhr | B24: =SUM(N24:R24,U24:Y24,AB24:AF24,AI24:AM24,AP24:AT24,AW24:BA24) -> 0 | C24: ='Preise RHH'!B20 -> 67 | D24: =IF(AND($G$9>=$R$9,$G$9<=$T$9),C24*$G$9*$V$9/100,IF(AND($G$9>=$R$8,$G$9<=$T$8),C24*$G$9*$V$8/100,IF(AND($G$9>=$R$7,$G$9<=$T$7),C24*$G$9*$V$7/100,IF($G$9>=$R$10,C24*$G$9*$V$10/100)))) -> 737 | E24: =B24*D24*(100+$G$10)/100 -> 0 | F24: =SUM(S24,Z24,AG24,AN24,AU24,BB24) -> 0 | G24: ='Preise RHH'!D20 -> 40 | H24: =IF(AND($G$9>=$R$9,$G$9<=$T$9),G24*$G$9*$V$9/100,IF(AND($G$9>=$R$8,$G$9<=$T$8),G24*$G$9*$V$8/100,IF(AND($G$9>=$R$7,$G$9<=$T$7),G24*$G$9*$V$7/100,IF($G$9>=$R$10,G24*$G$9*$V$10/100)))) -> 440 | I24: =F24*H24*(100+$G$10)/100 -> 0 | J24: =SUM(T24,AA24,AH24,AO24,AV24,BC24) -> 0 | K24: ='Preise RHH'!F20 -> 13 | L24: =IF(AND($G$9>=$R$9,$G$9<=$T$9),K24*$G$9*$V$9/100,IF(AND($G$9>=$R$8,$G$9<=$T$8),K24*$G$9*$V$8/100,IF(AND($G$9>=$R$7,$G$9<=$T$7),K24*$G$9*$V$7/100,IF($G$9>=$R$10,K24*$G$9*$V$10/100)))) -> 143 | M24: =J24*L24*(100+$G$10)/100 -> 0 | BF24: =IF($AJ7<12000,0,0.05) -> 0
A25: 8-9 Uhr | B25: =SUM(N25:R25,U25:Y25,AB25:AF25,AI25:AM25,AP25:AT25,AW25:BA25) -> 0 | C25: ='Preise RHH'!B21 -> 56 | D25: =IF(AND($G$9>=$R$9,$G$9<=$T$9),C25*$G$9*$V$9/100,IF(AND($G$9>=$R$8,$G$9<=$T$8),C25*$G$9*$V$8/100,IF(AND($G$9>=$R$7,$G$9<=$T$7),C25*$G$9*$V$7/100,IF($G$9>=$R$10,C25*$G$9*$V$10/100)))) -> 616 | E25: =B25*D25*(100+$G$10)/100 -> 0 | F25: =SUM(S25,Z25,AG25,AN25,AU25,BB25) -> 0 | G25: ='Preise RHH'!D21 -> 53 | H25: =IF(AND($G$9>=$R$9,$G$9<=$T$9),G25*$G$9*$V$9/100,IF(AND($G$9>=$R$8,$G$9<=$T$8),G25*$G$9*$V$8/100,IF(AND($G$9>=$R$7,$G$9<=$T$7),G25*$G$9*$V$7/100,IF($G$9>=$R$10,G25*$G$9*$V$10/100)))) -> 583 | I25: =F25*H25*(100+$G$10)/100 -> 0 | J25: =SUM(T25,AA25,AH25,AO25,AV25,BC25) -> 0 | K25: ='Preise RHH'!F21 -> 35 | L25: =IF(AND($G$9>=$R$9,$G$9<=$T$9),K25*$G$9*$V$9/100,IF(AND($G$9>=$R$8,$G$9<=$T$8),K25*$G$9*$V$8/100,IF(AND($G$9>=$R$7,$G$9<=$T$7),K25*$G$9*$V$7/100,IF($G$9>=$R$10,K25*$G$9*$V$10/100)))) -> 385 | M25: =J25*L25*(100+$G$10)/100 -> 0 | BF25: =SUM(BF22:BF24) -> 0 | BG25: =AI8 -> 0 | BH25: =BG25*(1-BF25) -> 0
A26: 9-10 Uhr | B26: =SUM(N26:R26,U26:Y26,AB26:AF26,AI26:AM26,AP26:AT26,AW26:BA26) -> 0 | C26: ='Preise RHH'!B22 -> 43 | D26: =IF(AND($G$9>=$R$9,$G$9<=$T$9),C26*$G$9*$V$9/100,IF(AND($G$9>=$R$8,$G$9<=$T$8),C26*$G$9*$V$8/100,IF(AND($G$9>=$R$7,$G$9<=$T$7),C26*$G$9*$V$7/100,IF($G$9>=$R$10,C26*$G$9*$V$10/100)))) -> 473 | E26: =B26*D26*(100+$G$10)/100 -> 0 | F26: =SUM(S26,Z26,AG26,AN26,AU26,BB26) -> 0 | G26: ='Preise RHH'!D22 -> 66 | H26: =IF(AND($G$9>=$R$9,$G$9<=$T$9),G26*$G$9*$V$9/100,IF(AND($G$9>=$R$8,$G$9<=$T$8),G26*$G$9*$V$8/100,IF(AND($G$9>=$R$7,$G$9<=$T$7),G26*$G$9*$V$7/100,IF($G$9>=$R$10,G26*$G$9*$V$10/100)))) -> 726 | I26: =F26*H26*(100+$G$10)/100 -> 0 | J26: =SUM(T26,AA26,AH26,AO26,AV26,BC26) -> 0 | K26: ='Preise RHH'!F22 -> 53 | L26: =IF(AND($G$9>=$R$9,$G$9<=$T$9),K26*$G$9*$V$9/100,IF(AND($G$9>=$R$8,$G$9<=$T$8),K26*$G$9*$V$8/100,IF(AND($G$9>=$R$7,$G$9<=$T$7),K26*$G$9*$V$7/100,IF($G$9>=$R$10,K26*$G$9*$V$10/100)))) -> 583 | M26: =J26*L26*(100+$G$10)/100 -> 0
A27: 10-11 Uhr | B27: =SUM(N27:R27,U27:Y27,AB27:AF27,AI27:AM27,AP27:AT27,AW27:BA27) -> 0 | C27: ='Preise RHH'!B23 -> 31 | D27: =IF(AND($G$9>=$R$9,$G$9<=$T$9),C27*$G$9*$V$9/100,IF(AND($G$9>=$R$8,$G$9<=$T$8),C27*$G$9*$V$8/100,IF(AND($G$9>=$R$7,$G$9<=$T$7),C27*$G$9*$V$7/100,IF($G$9>=$R$10,C27*$G$9*$V$10/100)))) -> 341 | E27: =B27*D27*(100+$G$10)/100 -> 0 | F27: =SUM(S27,Z27,AG27,AN27,AU27,BB27) -> 0 | G27: ='Preise RHH'!D23 -> 71 | H27: =IF(AND($G$9>=$R$9,$G$9<=$T$9),G27*$G$9*$V$9/100,IF(AND($G$9>=$R$8,$G$9<=$T$8),G27*$G$9*$V$8/100,IF(AND($G$9>=$R$7,$G$9<=$T$7),G27*$G$9*$V$7/100,IF($G$9>=$R$10,G27*$G$9*$V$10/100)))) -> 781 | I27: =F27*H27*(100+$G$10)/100 -> 0 | J27: =SUM(T27,AA27,AH27,AO27,AV27,BC27) -> 0 | K27: ='Preise RHH'!F23 -> 41 | L27: =IF(AND($G$9>=$R$9,$G$9<=$T$9),K27*$G$9*$V$9/100,IF(AND($G$9>=$R$8,$G$9<=$T$8),K27*$G$9*$V$8/100,IF(AND($G$9>=$R$7,$G$9<=$T$7),K27*$G$9*$V$7/100,IF($G$9>=$R$10,K27*$G$9*$V$10/100)))) -> 451 | M27: =J27*L27*(100+$G$10)/100 -> 0
A28: 11-12 Uhr | B28: =SUM(N28:R28,U28:Y28,AB28:AF28,AI28:AM28,AP28:AT28,AW28:BA28) -> 0 | C28: ='Preise RHH'!B24 -> 30 | D28: =IF(AND($G$9>=$R$9,$G$9<=$T$9),C28*$G$9*$V$9/100,IF(AND($G$9>=$R$8,$G$9<=$T$8),C28*$G$9*$V$8/100,IF(AND($G$9>=$R$7,$G$9<=$T$7),C28*$G$9*$V$7/100,IF($G$9>=$R$10,C28*$G$9*$V$10/100)))) -> 330 | E28: =B28*D28*(100+$G$10)/100 -> 0 | F28: =SUM(S28,Z28,AG28,AN28,AU28,BB28) -> 0 | G28: ='Preise RHH'!D24 -> 38 | H28: =IF(AND($G$9>=$R$9,$G$9<=$T$9),G28*$G$9*$V$9/100,IF(AND($G$9>=$R$8,$G$9<=$T$8),G28*$G$9*$V$8/100,IF(AND($G$9>=$R$7,$G$9<=$T$7),G28*$G$9*$V$7/100,IF($G$9>=$R$10,G28*$G$9*$V$10/100)))) -> 418 | I28: =F28*H28*(100+$G$10)/100 -> 0 | J28: =SUM(T28,AA28,AH28,AO28,AV28,BC28) -> 0 | K28: ='Preise RHH'!F24 -> 37 | L28: =IF(AND($G$9>=$R$9,$G$9<=$T$9),K28*$G$9*$V$9/100,IF(AND($G$9>=$R$8,$G$9<=$T$8),K28*$G$9*$V$8/100,IF(AND($G$9>=$R$7,$G$9<=$T$7),K28*$G$9*$V$7/100,IF($G$9>=$R$10,K28*$G$9*$V$10/100)))) -> 407 | M28: =J28*L28*(100+$G$10)/100 -> 0
A29: 12-13 Uhr | B29: =SUM(N29:R29,U29:Y29,AB29:AF29,AI29:AM29,AP29:AT29,AW29:BA29) -> 0 | C29: ='Preise RHH'!B25 -> 30 | D29: =IF(AND($G$9>=$R$9,$G$9<=$T$9),C29*$G$9*$V$9/100,IF(AND($G$9>=$R$8,$G$9<=$T$8),C29*$G$9*$V$8/100,IF(AND($G$9>=$R$7,$G$9<=$T$7),C29*$G$9*$V$7/100,IF($G$9>=$R$10,C29*$G$9*$V$10/100)))) -> 330 | E29: =B29*D29*(100+$G$10)/100 -> 0 | F29: =SUM(S29,Z29,AG29,AN29,AU29,BB29) -> 0 | G29: ='Preise RHH'!D25 -> 38 | H29: =IF(AND($G$9>=$R$9,$G$9<=$T$9),G29*$G$9*$V$9/100,IF(AND($G$9>=$R$8,$G$9<=$T$8),G29*$G$9*$V$8/100,IF(AND($G$9>=$R$7,$G$9<=$T$7),G29*$G$9*$V$7/100,IF($G$9>=$R$10,G29*$G$9*$V$10/100)))) -> 418 | I29: =F29*H29*(100+$G$10)/100 -> 0 | J29: =SUM(T29,AA29,AH29,AO29,AV29,BC29) -> 0 | K29: ='Preise RHH'!F25 -> 23 | L29: =IF(AND($G$9>=$R$9,$G$9<=$T$9),K29*$G$9*$V$9/100,IF(AND($G$9>=$R$8,$G$9<=$T$8),K29*$G$9*$V$8/100,IF(AND($G$9>=$R$7,$G$9<=$T$7),K29*$G$9*$V$7/100,IF($G$9>=$R$10,K29*$G$9*$V$10/100)))) -> 253 | M29: =J29*L29*(100+$G$10)/100 -> 0
A30: 13-14 Uhr | B30: =SUM(N30:R30,U30:Y30,AB30:AF30,AI30:AM30,AP30:AT30,AW30:BA30) -> 0 | C30: ='Preise RHH'!B26 -> 30 | D30: =IF(AND($G$9>=$R$9,$G$9<=$T$9),C30*$G$9*$V$9/100,IF(AND($G$9>=$R$8,$G$9<=$T$8),C30*$G$9*$V$8/100,IF(AND($G$9>=$R$7,$G$9<=$T$7),C30*$G$9*$V$7/100,IF($G$9>=$R$10,C30*$G$9*$V$10/100)))) -> 330 | E30: =B30*D30*(100+$G$10)/100 -> 0 | F30: =SUM(S30,Z30,AG30,AN30,AU30,BB30) -> 0 | G30: ='Preise RHH'!D26 -> 25 | H30: =IF(AND($G$9>=$R$9,$G$9<=$T$9),G30*$G$9*$V$9/100,IF(AND($G$9>=$R$8,$G$9<=$T$8),G30*$G$9*$V$8/100,IF(AND($G$9>=$R$7,$G$9<=$T$7),G30*$G$9*$V$7/100,IF($G$9>=$R$10,G30*$G$9*$V$10/100)))) -> 275 | I30: =F30*H30*(100+$G$10)/100 -> 0 | J30: =SUM(T30,AA30,AH30,AO30,AV30,BC30) -> 0 | K30: ='Preise RHH'!F26 -> 18 | L30: =IF(AND($G$9>=$R$9,$G$9<=$T$9),K30*$G$9*$V$9/100,IF(AND($G$9>=$R$8,$G$9<=$T$8),K30*$G$9*$V$8/100,IF(AND($G$9>=$R$7,$G$9<=$T$7),K30*$G$9*$V$7/100,IF($G$9>=$R$10,K30*$G$9*$V$10/100)))) -> 198 | M30: =J30*L30*(100+$G$10)/100 -> 0
A31: 14-15 Uhr | B31: =SUM(N31:R31,U31:Y31,AB31:AF31,AI31:AM31,AP31:AT31,AW31:BA31) -> 0 | C31: ='Preise RHH'!B27 -> 30 | D31: =IF(AND($G$9>=$R$9,$G$9<=$T$9),C31*$G$9*$V$9/100,IF(AND($G$9>=$R$8,$G$9<=$T$8),C31*$G$9*$V$8/100,IF(AND($G$9>=$R$7,$G$9<=$T$7),C31*$G$9*$V$7/100,IF($G$9>=$R$10,C31*$G$9*$V$10/100)))) -> 330 | E31: =B31*D31*(100+$G$10)/100 -> 0 | F31: =SUM(S31,Z31,AG31,AN31,AU31,BB31) -> 0 | G31: ='Preise RHH'!D27 -> 24 | H31: =IF(AND($G$9>=$R$9,$G$9<=$T$9),G31*$G$9*$V$9/100,IF(AND($G$9>=$R$8,$G$9<=$T$8),G31*$G$9*$V$8/100,IF(AND($G$9>=$R$7,$G$9<=$T$7),G31*$G$9*$V$7/100,IF($G$9>=$R$10,G31*$G$9*$V$10/100)))) -> 264 | I31: =F31*H31*(100+$G$10)/100 -> 0 | J31: =SUM(T31,AA31,AH31,AO31,AV31,BC31) -> 0 | K31: ='Preise RHH'!F27 -> 17 | L31: =IF(AND($G$9>=$R$9,$G$9<=$T$9),K31*$G$9*$V$9/100,IF(AND($G$9>=$R$8,$G$9<=$T$8),K31*$G$9*$V$8/100,IF(AND($G$9>=$R$7,$G$9<=$T$7),K31*$G$9*$V$7/100,IF($G$9>=$R$10,K31*$G$9*$V$10/100)))) -> 187 | M31: =J31*L31*(100+$G$10)/100 -> 0
A32: 15-16 Uhr | B32: =SUM(N32:R32,U32:Y32,AB32:AF32,AI32:AM32,AP32:AT32,AW32:BA32) -> 0 | C32: ='Preise RHH'!B28 -> 30 | D32: =IF(AND($G$9>=$R$9,$G$9<=$T$9),C32*$G$9*$V$9/100,IF(AND($G$9>=$R$8,$G$9<=$T$8),C32*$G$9*$V$8/100,IF(AND($G$9>=$R$7,$G$9<=$T$7),C32*$G$9*$V$7/100,IF($G$9>=$R$10,C32*$G$9*$V$10/100)))) -> 330 | E32: =B32*D32*(100+$G$10)/100 -> 0 | F32: =SUM(S32,Z32,AG32,AN32,AU32,BB32) -> 0 | G32: ='Preise RHH'!D28 -> 21 | H32: =IF(AND($G$9>=$R$9,$G$9<=$T$9),G32*$G$9*$V$9/100,IF(AND($G$9>=$R$8,$G$9<=$T$8),G32*$G$9*$V$8/100,IF(AND($G$9>=$R$7,$G$9<=$T$7),G32*$G$9*$V$7/100,IF($G$9>=$R$10,G32*$G$9*$V$10/100)))) -> 231 | I32: =F32*H32*(100+$G$10)/100 -> 0 | J32: =SUM(T32,AA32,AH32,AO32,AV32,BC32) -> 0 | K32: ='Preise RHH'!F28 -> 18 | L32: =IF(AND($G$9>=$R$9,$G$9<=$T$9),K32*$G$9*$V$9/100,IF(AND($G$9>=$R$8,$G$9<=$T$8),K32*$G$9*$V$8/100,IF(AND($G$9>=$R$7,$G$9<=$T$7),K32*$G$9*$V$7/100,IF($G$9>=$R$10,K32*$G$9*$V$10/100)))) -> 198 | M32: =J32*L32*(100+$G$10)/100 -> 0
A33: 16-17 Uhr | B33: =SUM(N33:R33,U33:Y33,AB33:AF33,AI33:AM33,AP33:AT33,AW33:BA33) -> 0 | C33: ='Preise RHH'!B29 -> 31 | D33: =IF(AND($G$9>=$R$9,$G$9<=$T$9),C33*$G$9*$V$9/100,IF(AND($G$9>=$R$8,$G$9<=$T$8),C33*$G$9*$V$8/100,IF(AND($G$9>=$R$7,$G$9<=$T$7),C33*$G$9*$V$7/100,IF($G$9>=$R$10,C33*$G$9*$V$10/100)))) -> 341 | E33: =B33*D33*(100+$G$10)/100 -> 0 | F33: =SUM(S33,Z33,AG33,AN33,AU33,BB33) -> 0 | G33: ='Preise RHH'!D29 -> 17 | H33: =IF(AND($G$9>=$R$9,$G$9<=$T$9),G33*$G$9*$V$9/100,IF(AND($G$9>=$R$8,$G$9<=$T$8),G33*$G$9*$V$8/100,IF(AND($G$9>=$R$7,$G$9<=$T$7),G33*$G$9*$V$7/100,IF($G$9>=$R$10,G33*$G$9*$V$10/100)))) -> 187 | I33: =F33*H33*(100+$G$10)/100 -> 0 | J33: =SUM(T33,AA33,AH33,AO33,AV33,BC33) -> 0 | K33: ='Preise RHH'!F29 -> 22 | L33: =IF(AND($G$9>=$R$9,$G$9<=$T$9),K33*$G$9*$V$9/100,IF(AND($G$9>=$R$8,$G$9<=$T$8),K33*$G$9*$V$8/100,IF(AND($G$9>=$R$7,$G$9<=$T$7),K33*$G$9*$V$7/100,IF($G$9>=$R$10,K33*$G$9*$V$10/100)))) -> 242 | M33: =J33*L33*(100+$G$10)/100 -> 0
A34: 17-18 Uhr | B34: =SUM(N34:R34,U34:Y34,AB34:AF34,AI34:AM34,AP34:AT34,AW34:BA34) -> 0 | C34: ='Preise RHH'!B30 -> 30 | D34: =IF(AND($G$9>=$R$9,$G$9<=$T$9),C34*$G$9*$V$9/100,IF(AND($G$9>=$R$8,$G$9<=$T$8),C34*$G$9*$V$8/100,IF(AND($G$9>=$R$7,$G$9<=$T$7),C34*$G$9*$V$7/100,IF($G$9>=$R$10,C34*$G$9*$V$10/100)))) -> 330 | E34: =B34*D34*(100+$G$10)/100 -> 0 | F34: =SUM(S34,Z34,AG34,AN34,AU34,BB34) -> 0 | G34: ='Preise RHH'!D30 -> 14 | H34: =IF(AND($G$9>=$R$9,$G$9<=$T$9),G34*$G$9*$V$9/100,IF(AND($G$9>=$R$8,$G$9<=$T$8),G34*$G$9*$V$8/100,IF(AND($G$9>=$R$7,$G$9<=$T$7),G34*$G$9*$V$7/100,IF($G$9>=$R$10,G34*$G$9*$V$10/100)))) -> 154 | I34: =F34*H34*(100+$G$10)/100 -> 0 | J34: =SUM(T34,AA34,AH34,AO34,AV34,BC34) -> 0 | K34: ='Preise RHH'!F30 -> 17 | L34: =IF(AND($G$9>=$R$9,$G$9<=$T$9),K34*$G$9*$V$9/100,IF(AND($G$9>=$R$8,$G$9<=$T$8),K34*$G$9*$V$8/100,IF(AND($G$9>=$R$7,$G$9<=$T$7),K34*$G$9*$V$7/100,IF($G$9>=$R$10,K34*$G$9*$V$10/100)))) -> 187 | M34: =J34*L34*(100+$G$10)/100 -> 0
A35: 18-19 Uhr | B35: =SUM(N35:R35,U35:Y35,AB35:AF35,AI35:AM35,AP35:AT35,AW35:BA35) -> 0 | C35: ='Preise RHH'!B31 -> 23 | D35: =IF(AND($G$9>=$R$9,$G$9<=$T$9),C35*$G$9*$V$9/100,IF(AND($G$9>=$R$8,$G$9<=$T$8),C35*$G$9*$V$8/100,IF(AND($G$9>=$R$7,$G$9<=$T$7),C35*$G$9*$V$7/100,IF($G$9>=$R$10,C35*$G$9*$V$10/100)))) -> 253 | E35: =B35*D35*(100+$G$10)/100 -> 0 | F35: =SUM(S35,Z35,AG35,AN35,AU35,BB35) -> 0 | G35: ='Preise RHH'!D31 -> 9 | H35: =IF(AND($G$9>=$R$9,$G$9<=$T$9),G35*$G$9*$V$9/100,IF(AND($G$9>=$R$8,$G$9<=$T$8),G35*$G$9*$V$8/100,IF(AND($G$9>=$R$7,$G$9<=$T$7),G35*$G$9*$V$7/100,IF($G$9>=$R$10,G35*$G$9*$V$10/100)))) -> 99 | I35: =F35*H35*(100+$G$10)/100 -> 0 | J35: =SUM(T35,AA35,AH35,AO35,AV35,BC35) -> 0 | K35: ='Preise RHH'!F31 -> 8 | L35: =IF(AND($G$9>=$R$9,$G$9<=$T$9),K35*$G$9*$V$9/100,IF(AND($G$9>=$R$8,$G$9<=$T$8),K35*$G$9*$V$8/100,IF(AND($G$9>=$R$7,$G$9<=$T$7),K35*$G$9*$V$7/100,IF($G$9>=$R$10,K35*$G$9*$V$10/100)))) -> 88 | M35: =J35*L35*(100+$G$10)/100 -> 0
A36: 19-20 Uhr | B36: =SUM(N36:R36,U36:Y36,AB36:AF36,AI36:AM36,AP36:AT36,AW36:BA36) -> 0 | C36: ='Preise RHH'!B32 -> 9 | D36: =IF(AND($G$9>=$R$9,$G$9<=$T$9),C36*$G$9*$V$9/100,IF(AND($G$9>=$R$8,$G$9<=$T$8),C36*$G$9*$V$8/100,IF(AND($G$9>=$R$7,$G$9<=$T$7),C36*$G$9*$V$7/100,IF($G$9>=$R$10,C36*$G$9*$V$10/100)))) -> 99 | E36: =B36*D36*(100+$G$10)/100 -> 0 | F36: =SUM(S36,Z36,AG36,AN36,AU36,BB36) -> 0 | G36: ='Preise RHH'!D32 -> 6 | H36: =IF(AND($G$9>=$R$9,$G$9<=$T$9),G36*$G$9*$V$9/100,IF(AND($G$9>=$R$8,$G$9<=$T$8),G36*$G$9*$V$8/100,IF(AND($G$9>=$R$7,$G$9<=$T$7),G36*$G$9*$V$7/100,IF($G$9>=$R$10,G36*$G$9*$V$10/100)))) -> 66 | I36: =F36*H36*(100+$G$10)/100 -> 0 | J36: =SUM(T36,AA36,AH36,AO36,AV36,BC36) -> 0 | K36: ='Preise RHH'!F32 -> 5 | L36: =IF(AND($G$9>=$R$9,$G$9<=$T$9),K36*$G$9*$V$9/100,IF(AND($G$9>=$R$8,$G$9<=$T$8),K36*$G$9*$V$8/100,IF(AND($G$9>=$R$7,$G$9<=$T$7),K36*$G$9*$V$7/100,IF($G$9>=$R$10,K36*$G$9*$V$10/100)))) -> 55 | M36: =J36*L36*(100+$G$10)/100 -> 0
A37: 20-21 Uhr | B37: =SUM(N37:R37,U37:Y37,AB37:AF37,AI37:AM37,AP37:AT37,AW37:BA37) -> 0 | C37: ='Preise RHH'!B33 -> 6 | D37: =IF(AND($G$9>=$R$9,$G$9<=$T$9),C37*$G$9*$V$9/100,IF(AND($G$9>=$R$8,$G$9<=$T$8),C37*$G$9*$V$8/100,IF(AND($G$9>=$R$7,$G$9<=$T$7),C37*$G$9*$V$7/100,IF($G$9>=$R$10,C37*$G$9*$V$10/100)))) -> 66 | E37: =B37*D37*(100+$G$10)/100 -> 0 | F37: =SUM(S37,Z37,AG37,AN37,AU37,BB37) -> 0 | G37: ='Preise RHH'!D33 -> 2 | H37: =IF(AND($G$9>=$R$9,$G$9<=$T$9),G37*$G$9*$V$9/100,IF(AND($G$9>=$R$8,$G$9<=$T$8),G37*$G$9*$V$8/100,IF(AND($G$9>=$R$7,$G$9<=$T$7),G37*$G$9*$V$7/100,IF($G$9>=$R$10,G37*$G$9*$V$10/100)))) -> 22 | I37: =F37*H37*(100+$G$10)/100 -> 0 | J37: =SUM(T37,AA37,AH37,AO37,AV37,BC37) -> 0 | K37: ='Preise RHH'!F33 -> 2 | L37: =IF(AND($G$9>=$R$9,$G$9<=$T$9),K37*$G$9*$V$9/100,IF(AND($G$9>=$R$8,$G$9<=$T$8),K37*$G$9*$V$8/100,IF(AND($G$9>=$R$7,$G$9<=$T$7),K37*$G$9*$V$7/100,IF($G$9>=$R$10,K37*$G$9*$V$10/100)))) -> 22 | M37: =J37*L37*(100+$G$10)/100 -> 0
... A40: 23-24 Uhr | B40: =SUM(N40:R40,U40:Y40,AB40:AF40,AI40:AM40,AP40:AT40,AW40:BA40) -> 0 | C40: ='Preise RHH'!B36 -> 2 | D40: =IF(AND($G$9>=$R$9,$G$9<=$T$9),C40*$G$9*$V$9/100,IF(AND($G$9>=$R$8,$G$9<=$T$8),C40*$G$9*$V$8/100,IF(AND($G$9>=$R$7,$G$9<=$T$7),C40*$G$9*$V$7/100,IF($G$9>=$R$10,C40*$G$9*$V$10/100)))) -> 22 | E40: =B40*D40*(100+$G$10)/100 -> 0 | F40: =SUM(S40,Z40,AG40,AN40,AU40,BB40) -> 0 | G40: ='Preise RHH'!D36 -> 1 | H40: =IF(AND($G$9>=$R$9,$G$9<=$T$9),G40*$G$9*$V$9/100,IF(AND($G$9>=$R$8,$G$9<=$T$8),G40*$G$9*$V$8/100,IF(AND($G$9>=$R$7,$G$9<=$T$7),G40*$G$9*$V$7/100,IF($G$9>=$R$10,G40*$G$9*$V$10/100)))) -> 11 | I40: =F40*H40*(100+$G$10)/100 -> 0 | J40: =SUM(T40,AA40,AH40,AO40,AV40,BC40) -> 0 | K40: ='Preise RHH'!F36 -> 1 | L40: =IF(AND($G$9>=$R$9,$G$9<=$T$9),K40*$G$9*$V$9/100,IF(AND($G$9>=$R$8,$G$9<=$T$8),K40*$G$9*$V$8/100,IF(AND($G$9>=$R$7,$G$9<=$T$7),K40*$G$9*$V$7/100,IF($G$9>=$R$10,K40*$G$9*$V$10/100)))) -> 11 | M40: =J40*L40*(100+$G$10)/100 -> 0
A41: SUMME | B41: =SUM(B17:B40) -> 0 | E41: =SUM(E17:E40) -> 0 | F41: =SUM(F17:F40) -> 0 | I41: =SUM(I17:I40) -> 0 | J41: =SUM(J17:J40) -> 0 | M41: =SUM(M17:M40) -> 0 | N41: =SUM(N22:N40) -> 0 | O41: =SUM(O22:O40) -> 0 | P41: =SUM(P22:P40) -> 0 | Q41: =SUM(Q22:Q40) -> 0 | R41: =SUM(R22:R40) -> 0 | S41: =SUM(S22:S40) -> 0 | T41: =SUM(T22:T40) -> 0 | U41: =SUM(U22:U40) -> 0 | ... BC41: =SUM(BC22:BC40) -> 0

Sheet Preise 80er 90er OAHH
A1: Preise 2026 (gültig ab 1. Januar 2026) | E1: Bitte Wochentag und Zeitschine per Dropdown auswählen. Anzahl der Spots, Sekundenlänge und ggf. Rabatte eingeben
E2: Berechnung | P2: Spotlängenbonus | T2: Index
E3: Wochentag | F3: Zeitschiene | G3: Anzahl Spots | H3: Invesition pro Spot | I3: Gesamtinvestition | J3: Abzgl. Cash-Rabatt | K3: Abzgl. 15%AE | L3: N/N Invest | M3: kummulierter Rabatt | N3: Payfaktor | P3: 1 | Q3: - | R3: 15 | S3: Sekunden | T3: 110
E4: Mo-So | F4: ø 08-24 | H4: =IF($E$4=$J$11,VLOOKUP($F$4,$A$37:$K$78,11,0),IF($E$4=$H$11,VLOOKUP($F$4,$A$37:$K$78,9,0),IF($E$4=$F$11,VLOOKUP($F$4,$A$37:$K$78,7,0),IF($E$4=$D$11,VLOOKUP($F$4,$A$37:$K$78,5,0),IF($E$4=$B$11,VLOOKUP($F$4,$A$37:$K$78,3,0)))))) -> 109.55357 | I4: =H4*G4 -> 0 | L4: =(I4-(I4*J4))-(I4-(I4*J4))*K4 -> 0 | M4: =1-L4/I4 -> #DIV/0! | N4: =(1-M4)*100 -> #DIV/0! | P4: 16 | Q4: - | R4: 24 | S4: Sekunden | T4: 105
E5: Mo-Fr | F5: ø 06-18 | H5: =IF($E$5=$J$11,VLOOKUP($F$5,$A$37:$K$78,11,0),IF($E$5=$H$11,VLOOKUP($F$5,$A$37:$K$78,9,0),IF($E$5=$F$11,VLOOKUP($F$5,$A$37:$K$78,7,0),IF($E$5=$D$11,VLOOKUP($F$5,$A$37:$K$78,5,0),IF($E$5=$B$11,VLOOKUP($F$5,$A$37:$K$78,3,0)))))) -> 150 | I5: =H5*G5 -> 0 | L5: =(I5-(I5*J5))-(I5-(I5*J5))*K5 -> 0 | M5: =1-L5/I5 -> #DIV/0! | N5: =(1-M5)*100 -> #DIV/0! | P5: 25 | Q5: - | R5: 34 | S5: Sekunden | T5: 100
E6: Mo-Fr | F6: ø 06-18 | H6: =IF($E$6=$J$11,VLOOKUP($F$6,$A$37:$K$78,11,0),IF($E$6=$H$11,VLOOKUP($F$6,$A$37:$K$78,9,0),IF($E$6=$F$11,VLOOKUP($F$6,$A$37:$K$78,7,0),IF($E$6=$D$11,VLOOKUP($F$6,$A$37:$K$78,5,0),IF($E$6=$B$11,VLOOKUP($F$6,$A$37:$K$78,3,0)))))) -> 150 | I6: =H6*G6 -> 0 | L6: =(I6-(I6*J6))-(I6-(I6*J6))*K6 -> 0 | M6: =1-L6/I6 -> #DIV/0! | N6: =(1-M6)*100 -> #DIV/0! | P6: 35 | Q6: - | R6: 99 | S6: Sekunden | T6: 95
A7: Sekundenlänge: | C7: 30 | E7: Mo-Fr | F7: ø 06-18 | H7: =IF($E$7=$J$11,VLOOKUP($F$7,$A$37:$K$78,11,0),IF($E$7=$H$11,VLOOKUP($F$7,$A$37:$K$78,9,0),IF($E$7=$F$11,VLOOKUP($F$7,$A$37:$K$78,7,0),IF($E$7=$D$11,VLOOKUP($F$7,$A$37:$K$78,5,0),IF($E$7=$B$11,VLOOKUP($F$7,$A$37:$K$78,3,0)))))) -> 150 | I7: =H7*G7 -> 0 | L7: =(I7-(I7*J7))-(I7-(I7*J7))*K7 -> 0 | M7: =1-L7/I7 -> #DIV/0! | N7: =(1-M7)*100 -> #DIV/0!
A8: Single-Spot max 45 Sek. Berechnung: Länge + 50% | L8: =SUM(L4:L7) -> 0
A9: Erst-Letzt-Platzierung Berechnung: Länge + 30%
A10: SPOTPREIS
B11: Mo-Fr | D11: Sa | F11: So | H11: MO-SA | J11: MO-SO
A12: ZEITSCHIENE | B12: €/SEK. (Index 100) | C12: €/SPOT | D12: €/SEK. (Index 100) | E12: €/SPOT | F12: €/SEK. (Index 100) | G12: €/SPOT | H12: €/SEK. (Index 100) | I12: €/SPOT | J12: €/SEK. (Index 100) | K12: €/SPOT
A13: 0-1 | B13: 1 | C13: =IF(AND($C$7>=$P$5,$C$7<=$R$5),B13*$C$7*$T$5/100,IF(AND($C$7>=$P$4,$C$7<=$R$4),B13*$C$7*$T$4/100,IF(AND($C$7>=$P$3,$C$7<=$R$3),B13*$C$7*$T$3/100,IF($C$7>=$P$6,B13*$C$7*$T$6/100)))) -> 30 | D13: 1 | E13: =IF(AND($C$7>=$P$5,$C$7<=$R$5),D13*$C$7*$T$5/100,IF(AND($C$7>=$P$4,$C$7<=$R$4),D13*$C$7*$T$4/100,IF(AND($C$7>=$P$3,$C$7<=$R$3),D13*$C$7*$T$3/100,IF($C$7>=$P$6,D13*$C$7*$T$6/100)))) -> 30 | F13: 1 | G13: =IF(AND($C$7>=$P$5,$C$7<=$R$5),F13*$C$7*$T$5/100,IF(AND($C$7>=$P$4,$C$7<=$R$4),F13*$C$7*$T$4/100,IF(AND($C$7>=$P$3,$C$7<=$R$3),F13*$C$7*$T$3/100,IF($C$7>=$P$6,F13*$C$7*$T$6/100)))) -> 30 | H13: =((B13*5)+D13)/6 -> 1 | I13: =IF(AND($C$7>=$P$5,$C$7<=$R$5),H13*$C$7*$T$5/100,IF(AND($C$7>=$P$4,$C$7<=$R$4),H13*$C$7*$T$4/100,IF(AND($C$7>=$P$3,$C$7<=$R$3),H13*$C$7*$T$3/100,IF($C$7>=$P$6,H13*$C$7*$T$6/100)))) -> 30 | J13: =((B13*5)+D13+F13)/7 -> 1 | K13: =IF(AND($C$7>=$P$5,$C$7<=$R$5),J13*$C$7*$T$5/100,IF(AND($C$7>=$P$4,$C$7<=$R$4),J13*$C$7*$T$4/100,IF(AND($C$7>=$P$3,$C$7<=$R$3),J13*$C$7*$T$3/100,IF($C$7>=$P$6,J13*$C$7*$T$6/100)))) -> 30
A14: 1-2 | B14: 1 | C14: =IF(AND($C$7>=$P$5,$C$7<=$R$5),B14*$C$7*$T$5/100,IF(AND($C$7>=$P$4,$C$7<=$R$4),B14*$C$7*$T$4/100,IF(AND($C$7>=$P$3,$C$7<=$R$3),B14*$C$7*$T$3/100,IF($C$7>=$P$6,B14*$C$7*$T$6/100)))) -> 30 | D14: 1 | E14: =IF(AND($C$7>=$P$5,$C$7<=$R$5),D14*$C$7*$T$5/100,IF(AND($C$7>=$P$4,$C$7<=$R$4),D14*$C$7*$T$4/100,IF(AND($C$7>=$P$3,$C$7<=$R$3),D14*$C$7*$T$3/100,IF($C$7>=$P$6,D14*$C$7*$T$6/100)))) -> 30 | F14: 1 | G14: =IF(AND($C$7>=$P$5,$C$7<=$R$5),F14*$C$7*$T$5/100,IF(AND($C$7>=$P$4,$C$7<=$R$4),F14*$C$7*$T$4/100,IF(AND($C$7>=$P$3,$C$7<=$R$3),F14*$C$7*$T$3/100,IF($C$7>=$P$6,F14*$C$7*$T$6/100)))) -> 30 | H14: =((B14*5)+D14)/6 -> 1 | I14: =IF(AND($C$7>=$P$5,$C$7<=$R$5),H14*$C$7*$T$5/100,IF(AND($C$7>=$P$4,$C$7<=$R$4),H14*$C$7*$T$4/100,IF(AND($C$7>=$P$3,$C$7<=$R$3),H14*$C$7*$T$3/100,IF($C$7>=$P$6,H14*$C$7*$T$6/100)))) -> 30 | J14: =((B14*5)+D14+F14)/7 -> 1 | K14: =IF(AND($C$7>=$P$5,$C$7<=$R$5),J14*$C$7*$T$5/100,IF(AND($C$7>=$P$4,$C$7<=$R$4),J14*$C$7*$T$4/100,IF(AND($C$7>=$P$3,$C$7<=$R$3),J14*$C$7*$T$3/100,IF($C$7>=$P$6,J14*$C$7*$T$6/100)))) -> 30
A15: 2-3 | B15: 1 | C15: =IF(AND($C$7>=$P$5,$C$7<=$R$5),B15*$C$7*$T$5/100,IF(AND($C$7>=$P$4,$C$7<=$R$4),B15*$C$7*$T$4/100,IF(AND($C$7>=$P$3,$C$7<=$R$3),B15*$C$7*$T$3/100,IF($C$7>=$P$6,B15*$C$7*$T$6/100)))) -> 30 | D15: 1 | E15: =IF(AND($C$7>=$P$5,$C$7<=$R$5),D15*$C$7*$T$5/100,IF(AND($C$7>=$P$4,$C$7<=$R$4),D15*$C$7*$T$4/100,IF(AND($C$7>=$P$3,$C$7<=$R$3),D15*$C$7*$T$3/100,IF($C$7>=$P$6,D15*$C$7*$T$6/100)))) -> 30 | F15: 1 | G15: =IF(AND($C$7>=$P$5,$C$7<=$R$5),F15*$C$7*$T$5/100,IF(AND($C$7>=$P$4,$C$7<=$R$4),F15*$C$7*$T$4/100,IF(AND($C$7>=$P$3,$C$7<=$R$3),F15*$C$7*$T$3/100,IF($C$7>=$P$6,F15*$C$7*$T$6/100)))) -> 30 | H15: =((B15*5)+D15)/6 -> 1 | I15: =IF(AND($C$7>=$P$5,$C$7<=$R$5),H15*$C$7*$T$5/100,IF(AND($C$7>=$P$4,$C$7<=$R$4),H15*$C$7*$T$4/100,IF(AND($C$7>=$P$3,$C$7<=$R$3),H15*$C$7*$T$3/100,IF($C$7>=$P$6,H15*$C$7*$T$6/100)))) -> 30 | J15: =((B15*5)+D15+F15)/7 -> 1 | K15: =IF(AND($C$7>=$P$5,$C$7<=$R$5),J15*$C$7*$T$5/100,IF(AND($C$7>=$P$4,$C$7<=$R$4),J15*$C$7*$T$4/100,IF(AND($C$7>=$P$3,$C$7<=$R$3),J15*$C$7*$T$3/100,IF($C$7>=$P$6,J15*$C$7*$T$6/100)))) -> 30
